Workbook

Sheet Summary
A1: Portfolio risk: Monte Carlo VaR, CVaR and drawdown
A2: Correlated GBM (Cholesky) | 10,000 simulations | horizon 252 trading days | data 2021-10-01 to 2026-09-30 (offline snapshot (prices_snapshot.csv)). Blue cells are inputs; everything else is a formula.
A4: Inputs | G4: Check: Excel vs Python | H4: Excel | I4: Python | J4: Difference
A5: Starting value ($) | B5: 100000 | G5: Mean | H5: =B18 -> 109117.08 | I5: 109117.08 | J5: =IFERROR(H5-I5,"n/a") -> 0
A6: Horizon (trading days) | B6: 252 | G6: Median | H6: =B19 -> 108067.6 | I6: 108067.6 | J6: =IFERROR(H6-I6,"n/a") -> 0
A7: Simulations | B7: =COUNT(Simulations!B:B) -> 10000 | G7: Standard deviation | H7: =B20 -> 12888.66 | I7: 12888.66 | J7: =IFERROR(H7-I7,"n/a") -> 0
A8: Method | B8: Correlated GBM (Cholesky) | G8: 5th percentile | H8: =B21 -> 90174.866 | I8: 90174.866 | J8: =IFERROR(H8-I8,"n/a") -> 0
A9: Rebalancing | B9: Buy and hold (weights drift) | G9: 25th percentile | H9: =B22 -> 100072.69 | I9: 100072.69 | J9: =IFERROR(H9-I9,"n/a") -> 0
A10: Random seed | B10: 42 | G10: 75th percentile | H10: =B23 -> 116972.91 | I10: 116972.91 | J10: =IFERROR(H10-I10,"n/a") -> 0
G11: 95th percentile | H11: =B24 -> 132007.79 | I11: 132007.79 | J11: =IFERROR(H11-I11,"n/a") -> 0
A12: Ticker | B12: Weight | G12: Minimum | H12: =B25 -> 71998.566 | I12: 71998.566 | J12: =IFERROR(H12-I12,"n/a") -> 0
A13: SPY | B13: 0.6 | G13: Maximum | H13: =B26 -> 184831.09 | I13: 184831.09 | J13: =IFERROR(H13-I13,"n/a") -> 0
A14: AGG | B14: 0.4 | G14: Probability of a loss | H14: =B27 -> 0.2481 | I14: 0.2481 | J14: =IFERROR(H14-I14,"n/a") -> 0
A15: Total | B15: =SUM(B13:B14) -> 1 | G15: MC VaR 95 $ | H15: =B31 -> 9825.1341 | I15: 9825.1341 | J15: =IFERROR(H15-I15,"n/a") -> 0
G16: MC CVaR 95 $ | H16: =B32 -> 13917.262 | I16: 13917.262 | J16: =IFERROR(H16-I16,"n/a") -> 0
A17: Simulated value after the horizon (formulas over 'Simulations') | G17: MC VaR 95 % | H17: =C31 -> 0.098251341 | I17: 0.098251341 | J17: =IFERROR(H17-I17,"n/a") -> 0
A18: Mean | B18: =AVERAGE(Simulations!$B$2:$B$10001) -> 109117.08 | G18: MC VaR 99 $ | H18: =B33 -> 16538.279 | I18: 16538.279 | J18: =IFERROR(H18-I18,"n/a") -> 0
A19: Median | B19: =MEDIAN(Simulations!$B$2:$B$10001) -> 108067.6 | G19: MC CVaR 99 $ | H19: =B34 -> 19250.047 | I19: 19250.047 | J19: =IFERROR(H19-I19,"n/a") -> 0
A20: Standard deviation | B20: =_xlfn.STDEV.S(Simulations!$B$2:$B$10001) -> 12888.66 | G20: MC VaR 99 % | H20: =C33 -> 0.16538279 | I20: 0.16538279 | J20: =IFERROR(H20-I20,"n/a") -> 0
A21: 5th percentile | B21: =_xlfn.PERCENTILE.INC(Simulations!$B$2:$B$10001,0.05) -> 90174.866 | G21: Median max drawdown | H21: =B37 -> 0.091195186 | I21: 0.091195186 | J21: =IFERROR(H21-I21,"n/a") -> 0
A22: 25th percentile | B22: =_xlfn.PERCENTILE.INC(Simulations!$B$2:$B$10001,0.25) -> 100072.69 | G22: 95th percentile max drawdown | H22: =B38 -> 0.17207844 | I22: 0.17207844 | J22: =IFERROR(H22-I22,"n/a") -> 0
A23: 75th percentile | B23: =_xlfn.PERCENTILE.INC(Simulations!$B$2:$B$10001,0.75) -> 116972.91 | G23: Worst max drawdown | H23: =B39 -> 0.31523921 | I23: 0.31523921 | J23: =IFERROR(H23-I23,"n/a") -> 0
A24: 95th percentile | B24: =_xlfn.PERCENTILE.INC(Simulations!$B$2:$B$10001,0.95) -> 132007.79 | G24: Hist mean daily log return | H24: =B42 -> 0.00030434701 | I24: 0.00030434701 | J24: =IFERROR(H24-I24,"n/a") -> 0
A25: Minimum | B25: =MIN(Simulations!$B$2:$B$10001) -> 71998.566 | G25: Hist daily volatility | H25: =B43 -> 0.0069888004 | I25: 0.0069888004 | J25: =IFERROR(H25-I25,"n/a") -> 0
A26: Maximum | B26: =MAX(Simulations!$B$2:$B$10001) -> 184831.09 | G26: Parametric VaR 95 % | H26: =B49 -> 0.10038718 | I26: 0.10038718 | J26: =IFERROR(H26-I26,"n/a") -> 0
A27: Probability of a loss | B27: =COUNTIF(Simulations!$B$2:$B$10001,"<"&$B$5)/COUNT(Simulations!$B$2:$B$10001) -> 0.2481 | G27: Parametric CVaR 95 % | H27: =C49 -> 0.14042462 | I27: 0.14042462 | J27: =IFERROR(H27-I27,"n/a") -> -2.6645353e-15
G28: Parametric VaR 99 % | H28: =D49 -> 0.16589697 | I28: 0.16589697 | J28: =IFERROR(H28-I28,"n/a") -> 0
A29: Monte Carlo VaR and CVaR (positive = loss over the horizon)
A30: Measure | B30: Loss ($) | C30: Loss (% of start)
A31: VaR 95% | B31: =$B$5-_xlfn.PERCENTILE.INC(Simulations!$B$2:$B$10001,0.05) -> 9825.1341 | C31: =B31/$B$5 -> 0.098251341
A32: CVaR 95% (expected shortfall) | B32: =$B$5-AVERAGEIF(Simulations!$B$2:$B$10001,"<="&($B$5-B31)) -> 13917.262 | C32: =B32/$B$5 -> 0.13917262
A33: VaR 99% | B33: =$B$5-_xlfn.PERCENTILE.INC(Simulations!$B$2:$B$10001,0.01) -> 16538.279 | C33: =B33/$B$5 -> 0.16538279
A34: CVaR 99% (expected shortfall) | B34: =$B$5-AVERAGEIF(Simulations!$B$2:$B$10001,"<="&($B$5-B33)) -> 19250.047 | C34: =B34/$B$5 -> 0.19250047
A36: Maximum drawdown per path (positive = fall from the running peak)
A37: Median max drawdown | B37: =MEDIAN(Simulations!$C$2:$C$10001) -> 0.091195186
A38: 95th percentile max drawdown | B38: =_xlfn.PERCENTILE.INC(Simulations!$C$2:$C$10001,0.95) -> 0.17207844
A39: Worst max drawdown | B39: =MAX(Simulations!$C$2:$C$10001) -> 0.31523921
A41: Comparison on 1,253 historical daily returns (formulas over 'History')
A42: Mean daily log return (portfolio) | B42: =AVERAGE(History!$F$3:$F$1255) -> 0.00030434701
A43: Daily volatility (portfolio) | B43: =_xlfn.STDEV.S(History!$F$3:$F$1255) -> 0.0069888004
...

Sheet History
A1: Date | B1: SPY price | C1: AGG price | D1: SPY log return | E1: AGG log return | F1: Portfolio log return (daily rebalanced) | G1: Portfolio simple return | H1: 252-day return (window ending here)
A2: 44470 | B2: 406.14572 | C2: 97.835541
A3: 44473 | B3: 400.90805 | C3: 97.767494 | D3: =LN(B3/B2) -> -0.012979912 | E3: =LN(C3/C2) -> -0.00069576633 | F3: =LN(Summary!$B$13*EXP(D3)+Summary!$B$14*EXP(E3)) -> -0.0080481311 | G3: =EXP(F3)-1 -> -0.0080158316
A4: 44474 | B4: 405.07947 | C4: 97.537788 | D4: =LN(B4/B3) -> 0.010351163 | E4: =LN(C4/C3) -> -0.0023522775 | F4: =LN(Summary!$B$13*EXP(D4)+Summary!$B$14*EXP(E4)) -> 0.0052891358 | G4: =EXP(F4)-1 -> 0.005303148
A5: 44475 | B5: 406.76306 | C5: 97.580315 | D5: =LN(B5/B4) -> 0.0041475935 | E5: =LN(C5/C4) -> 0.00043591035 | F5: =LN(Summary!$B$13*EXP(D5)+Summary!$B$14*EXP(E5)) -> 0.002664573 | G5: =EXP(F5)-1 -> 0.0026681262
A6: 44476 | B6: 410.27972 | C6: 97.308098 | D6: =LN(B6/B5) -> 0.0086083221 | E6: =LN(C6/C5) -> -0.0027935696 | F6: =LN(Summary!$B$13*EXP(D6)+Summary!$B$14*EXP(E6)) -> 0.0040631538 | G6: =EXP(F6)-1 -> 0.0040714196
A7: 44477 | B7: 409.53149 | C7: 97.095352 | D7: =LN(B7/B6) -> -0.001825372 | E7: =LN(C7/C6) -> -0.0021887069 | F7: =LN(Summary!$B$13*EXP(D7)+Summary!$B$14*EXP(E7)) -> -0.0019706901 | G7: =EXP(F7)-1 -> -0.0019687496
A8: 44480 | B8: 406.56659 | C8: 96.942261 | D8: =LN(B8/B7) -> -0.0072660826 | E8: =LN(C8/C7) -> -0.0015779521 | F8: =LN(Summary!$B$13*EXP(D8)+Summary!$B$14*EXP(E8)) -> -0.0049869464 | G8: =EXP(F8)-1 -> -0.0049745322
A9: 44481 | B9: 405.56583 | C9: 97.299568 | D9: =LN(B9/B8) -> -0.0024645328 | E9: =LN(C9/C8) -> 0.0036789955 | F9: =LN(Summary!$B$13*EXP(D9)+Summary!$B$14*EXP(E9)) -> -2.5905249e-06 | G9: =EXP(F9)-1 -> -2.5905216e-06
A10: 44482 | B10: 407.02484 | C10: 97.520782 | D10: =LN(B10/B9) -> 0.0035910247 | E10: =LN(C10/C9) -> 0.0022709547 | F10: =LN(Summary!$B$13*EXP(D10)+Summary!$B$14*EXP(E10)) -> 0.0030632058 | G10: =EXP(F10)-1 -> 0.0030679022
A11: 44483 | B11: 413.87137 | C11: 97.707886 | D11: =LN(B11/B10) -> 0.016681002 | E11: =LN(C11/C10) -> 0.0019167683 | F11: =LN(Summary!$B$13*EXP(D11)+Summary!$B$14*EXP(E11)) -> 0.010801441 | G11: =EXP(F11)-1 -> 0.010859987
A12: 44484 | B12: 417.02332 | C12: 97.469681 | D12: =LN(B12/B11) -> 0.0075869113 | E12: =LN(C12/C11) -> -0.0024409067 | F12: =LN(Summary!$B$13*EXP(D12)+Summary!$B$14*EXP(E12)) -> 0.0035878428 | G12: =EXP(F12)-1 -> 0.0035942868
A13: 44487 | B13: 418.25787 | C13: 97.401672 | D13: =LN(B13/B12) -> 0.0029560342 | E13: =LN(C13/C12) -> -0.00069798872 | F13: =LN(Summary!$B$13*EXP(D13)+Summary!$B$14*EXP(E13)) -> 0.0014960269 | G13: =EXP(F13)-1 -> 0.0014971465
A14: 44488 | B14: 421.48471 | C14: 97.120941 | D14: =LN(B14/B13) -> 0.0076853382 | E14: =LN(C14/C13) -> -0.0028863605 | F14: =LN(Summary!$B$13*EXP(D14)+Summary!$B$14*EXP(E14)) -> 0.0034700605 | G14: =EXP(F14)-1 -> 0.0034760881
... A253: 44834 | B253: 339.12653 | C253: 83.428146 | D253: =LN(B253/B252) -> -0.015584477 | E253: =LN(C253/C252) -> -0.0023845146 | F253: =LN(Summary!$B$13*EXP(D253)+Summary!$B$14*EXP(E253)) -> -0.010283565 | G253: =EXP(F253)-1 -> -0.01023087
A254: 44837 | B254: 348.0798 | C254: 84.10598 | D254: =LN(B254/B253) -> 0.026058502 | E254: =LN(C254/C253) -> 0.0080919358 | F254: =LN(Summary!$B$13*EXP(D254)+Summary!$B$14*EXP(E254)) -> 0.018910564 | G254: =EXP(F254)-1 -> 0.019090501 | H254: =EXP(SUM(F3:F254))-1 -> -0.1370587
A255: 44838 | B255: 358.86569 | C255: 84.331604 | D255: =LN(B255/B254) -> 0.030516429 | E255: =LN(C255/C254) -> 0.0026790236 | F255: =LN(Summary!$B$13*EXP(D255)+Summary!$B$14*EXP(E255)) -> 0.019474282 | G255: =EXP(F255)-1 -> 0.019665143 | H255: =EXP(SUM(F4:F255))-1 -> -0.11297862
A256: 44839 | B256: 358.03015 | C256: 83.888985 | D256: =LN(B256/B255) -> -0.002330998 | E256: =LN(C256/C255) -> -0.0052623763 | F256: =LN(Summary!$B$13*EXP(D256)+Summary!$B$14*EXP(E256)) -> -0.0035025184 | G256: =EXP(F256)-1 -> -0.0034963917 | H256: =EXP(SUM(F5:F256))-1 -> -0.12074282
A257: 44840 | B257: 354.33682 | C257: 83.559189 | D257: =LN(B257/B256) -> -0.010369265 | E257: =LN(C257/C256) -> -0.0039390866 | F257: =LN(Summary!$B$13*EXP(D257)+Summary!$B$14*EXP(E257)) -> -0.0077922301 | G257: =EXP(F257)-1 -> -0.0077619493 | H257: =EXP(SUM(F6:F257))-1 -> -0.12988914
A258: 44841 | B258: 344.45303 | C258: 83.116608 | D258: =LN(B258/B257) -> -0.028290191 | E258: =LN(C258/C257) -> -0.0053106936 | F258: =LN(Summary!$B$13*EXP(D258)+Summary!$B$14*EXP(E258)) -> -0.019034929 | G258: =EXP(F258)-1 -> -0.018854909 | H258: =EXP(SUM(F7:F258))-1 -> -0.1497567
A259: 44844 | B259: 341.82294 | C259: 82.743362 | D259: =LN(B259/B258) -> -0.0076648724 | E259: =LN(C259/C258) -> -0.004500744 | F259: =LN(Summary!$B$13*EXP(D259)+Summary!$B$14*EXP(E259)) -> -0.0063980194 | G259: =EXP(F259)-1 -> -0.0063775956 | H259: =EXP(SUM(F8:F259))-1 -> -0.15351268
A260: 44845 | B260: 339.65814 | C260: 82.795464 | D260: =LN(B260/B259) -> -0.0063532278 | E260: =LN(C260/C259) -> 0.00062948376 | F260: =LN(Summary!$B$13*EXP(D260)+Summary!$B$14*EXP(E260)) -> -0.0035542895 | G260: =EXP(F260)-1 -> -0.0035479805 | H260: =EXP(SUM(F9:F260))-1 -> -0.15229909
A261: 44846 | B261: 338.53781 | C261: 82.864906 | D261: =LN(B261/B260) -> -0.0033038593 | E261: =LN(C261/C260) -> 0.00083836592 | F261: =LN(Summary!$B$13*EXP(D261)+Summary!$B$14*EXP(E261)) -> -0.0016449097 | G261: =EXP(F261)-1 -> -0.0016435576 | H261: =EXP(SUM(F10:F261))-1 -> -0.15369014
A262: 44847 | B262: 347.47226 | C262: 82.604546 | D262: =LN(B262/B261) -> 0.026049047 | E262: =LN(C262/C261) -> -0.0031469279 | F262: =LN(Summary!$B$13*EXP(D262)+Summary!$B$14*EXP(E262)) -> 0.014472743 | G262: =EXP(F262)-1 -> 0.01457798 | H262: =EXP(SUM(F11:F262))-1 -> -0.14397884
A263: 44848 | B263: 339.55374 | C263: 82.153229 | D263: =LN(B263/B262) -> -0.023052605 | E263: =LN(C263/C262) -> -0.0054785655 | F263: =LN(Summary!$B$13*EXP(D263)+Summary!$B$14*EXP(E263)) -> -0.015985885 | G263: =EXP(F263)-1 -> -0.015858789 | H263: =EXP(SUM(F12:F263))-1 -> -0.16660496
A264: 44851 | B264: 348.27927 | C264: 82.326828 | D264: =LN(B264/B263) -> 0.025372417 | E264: =LN(C264/C263) -> 0.0021108828 | F264: =LN(Summary!$B$13*EXP(D264)+Summary!$B$14*EXP(E264)) -> 0.016132633 | G264: =EXP(F264)-1 -> 0.016263467 | H264: =EXP(SUM(F13:F264))-1 -> -0.15608434
A265: 44852 | B265: 352.37143 | C265: 82.465683 | D265: =LN(B265/B264) -> 0.011681169 | E265: =LN(C265/C264) -> 0.0016852105 | F265: =LN(Summary!$B$13*EXP(D265)+Summary!$B$14*EXP(E265)) -> 0.0076947678 | G265: =EXP(F265)-1 -> 0.0077244486 | H265: =EXP(SUM(F14:F265))-1 -> -0.15083688
... A1255: 46295 | B1255: 762.63 | C1255: 94.540001 | D1255: =LN(B1255/B1254) -> -0.0020565584 | E1255: =LN(C1255/C1254) -> -0.00063441897 | F1255: =LN(Summary!$B$13*EXP(D1255)+Summary!$B$14*EXP(E1255)) -> -0.0014874599 | G1255: =EXP(F1255)-1 -> -0.0014863542 | H1255: =EXP(SUM(F1004:F1255))-1 -> 0.087586443

Sheet Simulations
A1: Simulation | B1: Value after horizon ($) | C1: Max drawdown | D1: Loss ($) | E1: Return
A2: 1 | B2: 89981.384 | C2: 0.15563522 | D2: =Summary!$B$5-B2 -> 10018.616 | E2: =B2/Summary!$B$5-1 -> -0.10018616
A3: 2 | B3: 111342.44 | C3: 0.086461929 | D3: =Summary!$B$5-B3 -> -11342.436 | E3: =B3/Summary!$B$5-1 -> 0.11342436
A4: 3 | B4: 106806.7 | C4: 0.082576243 | D4: =Summary!$B$5-B4 -> -6806.7016 | E4: =B4/Summary!$B$5-1 -> 0.068067016
A5: 4 | B5: 103938.35 | C5: 0.075139818 | D5: =Summary!$B$5-B5 -> -3938.3547 | E5: =B5/Summary!$B$5-1 -> 0.039383547
A6: 5 | B6: 119560.91 | C6: 0.11798565 | D6: =Summary!$B$5-B6 -> -19560.911 | E6: =B6/Summary!$B$5-1 -> 0.19560911
A7: 6 | B7: 103518.89 | C7: 0.084106662 | D7: =Summary!$B$5-B7 -> -3518.8889 | E7: =B7/Summary!$B$5-1 -> 0.035188889
A8: 7 | B8: 93099.198 | C8: 0.14913156 | D8: =Summary!$B$5-B8 -> 6900.8016 | E8: =B8/Summary!$B$5-1 -> -0.069008016
A9: 8 | B9: 98225.938 | C9: 0.10592186 | D9: =Summary!$B$5-B9 -> 1774.062 | E9: =B9/Summary!$B$5-1 -> -0.01774062
A10: 9 | B10: 111213.92 | C10: 0.084994506 | D10: =Summary!$B$5-B10 -> -11213.916 | E10: =B10/Summary!$B$5-1 -> 0.11213916
A11: 10 | B11: 140250.53 | C11: 0.053618696 | D11: =Summary!$B$5-B11 -> -40250.526 | E11: =B11/Summary!$B$5-1 -> 0.40250526
A12: 11 | B12: 112392.52 | C12: 0.083286528 | D12: =Summary!$B$5-B12 -> -12392.519 | E12: =B12/Summary!$B$5-1 -> 0.12392519
A13: 12 | B13: 130138.47 | C13: 0.072347887 | D13: =Summary!$B$5-B13 -> -30138.469 | E13: =B13/Summary!$B$5-1 -> 0.30138469
... A10001: 10000 | B10001: 126472.36 | C10001: 0.052668412 | D10001: =Summary!$B$5-B10001 -> -26472.357 | E10001: =B10001/Summary!$B$5-1 -> 0.26472357

Sheet Sample Paths
A1: Day | B1: Path 1 | C1: Path 2 | D1: Path 3 | E1: Path 4 | F1: Path 5 | G1: Path 6 | H1: Path 7 | I1: Path 8 | J1: Path 9 | K1: Path 10 | L1: Path 11 | M1: Path 12 | N1: Path 13 | O1: Path 14 | P1: Path 15 | Q1: Path 16 | R1: Path 17 | S1: Path 18 | T1: Path 19 | U1: Path 20 | V1: Path 21 | W1: Path 22 | X1: Path 23 | Y1: Path 24 | Z1: Path 25
A2: 0 | B2: 100000 | C2: 100000 | D2: 100000 | E2: 100000 | F2: 100000 | G2: 100000 | H2: 100000 | I2: 100000 | J2: 100000 | K2: 100000 | L2: 100000 | M2: 100000 | N2: 100000 | O2: 100000 | P2: 100000 | Q2: 100000 | R2: 100000 | S2: 100000 | T2: 100000 | U2: 100000 | V2: 100000 | W2: 100000 | X2: 100000 | Y2: 100000 | Z2: 100000
A3: 1 | B3: 100080.75 | C3: 100685.45 | D3: 98515.24 | E3: 100068.71 | F3: 99889.15 | G3: 100749.56 | H3: 100244.58 | I3: 100219.44 | J3: 100136.79 | K3: 100623.78 | L3: 99800.47 | M3: 100845.37 | N3: 99684.35 | O3: 100448.55 | P3: 100376.42 | Q3: 101445.54 | R3: 99557.9 | S3: 100621.56 | T3: 99824.84 | U3: 99566.98 | V3: 100620.34 | W3: 99611.47 | X3: 100141.77 | Y3: 100660.25 | Z3: 100504.24
A4: 2 | B4: 99118.04 | C4: 100584.1 | D4: 98531.76 | E4: 100580.36 | F4: 98985.09 | G4: 101106.76 | H4: 100601.19 | I4: 100676.54 | J4: 99258.96 | K4: 101161.1 | L4: 100655.63 | M4: 103308 | N4: 99858.89 | O4: 101341.49 | P4: 99784.9 | Q4: 102715.21 | R4: 98645.35 | S4: 101974.35 | T4: 100217.29 | U4: 98640.23 | V4: 100693.71 | W4: 100528.13 | X4: 100330.21 | Y4: 100755.93 | Z4: 101505.49
A5: 3 | B5: 98354.53 | C5: 100865.87 | D5: 96896.57 | E5: 100774.96 | F5: 98834.54 | G5: 100051.95 | H5: 100885.89 | I5: 100749.22 | J5: 98466.28 | K5: 99704.59 | L5: 100979.03 | M5: 104116.88 | N5: 98507.92 | O5: 100644.74 | P5: 98236.49 | Q5: 103333.95 | R5: 98498.34 | S5: 101611.26 | T5: 100563.62 | U5: 97997.33 | V5: 101120.15 | W5: 99820.69 | X5: 100169.62 | Y5: 101305.31 | Z5: 100552.94
A6: 4 | B6: 98860.94 | C6: 101806.37 | D6: 95549.72 | E6: 101251.41 | F6: 98933.21 | G6: 100128.74 | H6: 101996.11 | I6: 100628.24 | J6: 97783.3 | K6: 98747.3 | L6: 102230.72 | M6: 104130.07 | N6: 98376.5 | O6: 101601.46 | P6: 97711.88 | Q6: 102843.91 | R6: 99757.48 | S6: 100976.04 | T6: 100157.92 | U6: 99420.45 | V6: 101646.44 | W6: 99718.95 | X6: 101813.92 | Y6: 100928.11 | Z6: 100409.19
A7: 5 | B7: 99432.41 | C7: 102395.04 | D7: 95273.74 | E7: 101191.67 | F7: 99910.15 | G7: 99305.81 | H7: 102114.41 | I7: 99491.09 | J7: 98715.94 | K7: 98454.17 | L7: 103292.03 | M7: 103902.92 | N7: 98444.37 | O7: 100762.03 | P7: 97965.6 | Q7: 102471.74 | R7: 100051.62 | S7: 100740.92 | T7: 100752.96 | U7: 99925.46 | V7: 101169.51 | W7: 99141.61 | X7: 101417.77 | Y7: 100507.63 | Z7: 101060.56
A8: 6 | B8: 98762 | C8: 103578.6 | D8: 96163.4 | E8: 100757.34 | F8: 99434.51 | G8: 99899.95 | H8: 102076.14 | I8: 99752.11 | J8: 98292.34 | K8: 98448.48 | L8: 102256.99 | M8: 104603.36 | N8: 97778.51 | O8: 99992.6 | P8: 97311.73 | Q8: 102002.36 | R8: 99847.27 | S8: 100965.89 | T8: 99660.5 | U8: 100722.3 | V8: 100970.93 | W8: 99047.48 | X8: 102695.6 | Y8: 100056.39 | Z8: 100545.74
A9: 7 | B9: 99431.84 | C9: 103331.75 | D9: 95214.79 | E9: 99874.69 | F9: 99505.86 | G9: 101316.38 | H9: 103116.17 | I9: 100950.24 | J9: 99681.92 | K9: 99015.81 | L9: 101840.61 | M9: 104047.52 | N9: 97041.27 | O9: 101458.26 | P9: 96932.98 | Q9: 101954.16 | R9: 100272.42 | S9: 100655.04 | T9: 98599.1 | U9: 100209.98 | V9: 101567.05 | W9: 98944.28 | X9: 102601.04 | Y9: 100577.23 | Z9: 101170.62
A10: 8 | B10: 98479.18 | C10: 104185.63 | D10: 95788.1 | E10: 100033.58 | F10: 99604.79 | G10: 101266.15 | H10: 102876.19 | I10: 100824.32 | J10: 100974.43 | K10: 98139.88 | L10: 100706.29 | M10: 102790.98 | N10: 98227.85 | O10: 101976.78 | P10: 97147.26 | Q10: 101622.95 | R10: 100577.66 | S10: 100788.07 | T10: 98071.6 | U10: 100950.88 | V10: 100899.79 | W10: 99255.08 | X10: 102582.83 | Y10: 100700.18 | Z10: 101626.79
A11: 9 | B11: 96737.31 | C11: 104420.76 | D11: 96273.08 | E11: 99095.27 | F11: 98736.67 | G11: 102223.58 | H11: 103055.6 | I11: 99488.84 | J11: 100130.69 | K11: 97525.1 | L11: 101961.84 | M11: 102552.68 | N11: 98516.21 | O11: 102146.02 | P11: 96584.06 | Q11: 103147.45 | R11: 100755.63 | S11: 99736.63 | T11: 97362.08 | U11: 100935.91 | V11: 100740.08 | W11: 100380.21 | X11: 103319.4 | Y11: 99976.36 | Z11: 102682.88
A12: 10 | B12: 97887.86 | C12: 103661.33 | D12: 96476.93 | E12: 100408.48 | F12: 98181.2 | G12: 101928.59 | H12: 101514.44 | I12: 98165.18 | J12: 101010.43 | K12: 98112.78 | L12: 102062.58 | M12: 102300.57 | N12: 98733.29 | O12: 102191.58 | P12: 96151.15 | Q12: 103475.08 | R12: 100466.85 | S12: 99413.82 | T12: 98923.6 | U12: 101733.34 | V12: 101226.3 | W12: 99167.7 | X12: 104022.49 | Y12: 99553.53 | Z12: 102754.49
A13: 11 | B13: 99633.4 | C13: 103187.03 | D13: 96297.9 | E13: 100325.96 | F13: 97429.22 | G13: 101386.76 | H13: 102216.42 | I13: 97928.78 | J13: 100646.52 | K13: 99814.95 | L13: 102748.94 | M13: 102396.61 | N13: 98704.43 | O13: 101546.57 | P13: 96335.18 | Q13: 103088.34 | R13: 100303.41 | S13: 98841.67 | T13: 99838.55 | U13: 102491.96 | V13: 101621.69 | W13: 99132.34 | X13: 104888.39 | Y13: 98654.09 | Z13: 102961.73
... A254: 252 | B254: 89981.38 | C254: 111342.44 | D254: 106806.7 | E254: 103938.35 | F254: 119560.91 | G254: 103518.89 | H254: 93099.2 | I254: 98225.94 | J254: 111213.92 | K254: 140250.53 | L254: 112392.52 | M254: 130138.47 | N254: 134691.61 | O254: 110293.15 | P254: 83657.89 | Q254: 113133.03 | R254: 96802.9 | S254: 88486.79 | T254: 103514.15 | U254: 103918.99 | V254: 108473.24 | W254: 102752.23 | X254: 97720.24 | Y254: 100100.59 | Z254: 107555.98
