Workbook

Sheet Summary
A1: Retirement plan: Monte Carlo probability of success
A2: 10,000 simulations of monthly returns | 25 years saving + 30 years spending. Blue cells are inputs; everything else is a formula.
A4: Inputs | D4: Check: Excel vs Python | E4: Excel | F4: Python | G4: Difference
A5: Starting savings ($) | B5: 50000 | D5: Monthly log drift | E5: =B17 -> 0.0047007207 | F5: 0.0047007207 | G5: =IFERROR(E5-F5,"n/a") -> 0
A6: Monthly contribution ($) | B6: 1000 | D6: Monthly log volatility | E6: =B18 -> 0.04330127 | F6: 0.04330127 | G6: =IFERROR(E6-F6,"n/a") -> 0
A7: Years until retirement | B7: 25 | D7: Median (typical) annual return | E7: =B19 -> 0.058029958 | F7: 0.058029958 | G7: =IFERROR(E7-F7,"n/a") -> 0
A8: Years in retirement | B8: 30 | D8: First-year withdrawal in retirement ($) | E8: =B20 -> 60000 | F8: 60000 | G8: =IFERROR(E8-F8,"n/a") -> 0
A9: Annual withdrawal ($) | B9: 60000 | D9: Nest egg with no volatility ($) | E9: =B21 -> 1054413.5 | F9: 1054413.5 | G9: =IFERROR(E9-F9,"n/a") -> 0
A10: Withdrawal stated in today's money? (1 = yes) | B10: 0 | D10: Probability of success | E10: =B24 -> 0.3433 | F10: 0.3433 | G10: =IFERROR(E10-F10,"n/a") -> 0
A11: Inflation (per year) | B11: 0.025 | D11: Failed simulations | E11: =B25 -> 6567 | F11: 6567 | G11: =IFERROR(E11-F11,"n/a") -> 0
A12: Expected return (arithmetic, per year) | B12: 0.07 | D12: Median nest egg at retirement ($) | E12: =B26 -> 889155.36 | F12: 889155.36 | G12: =IFERROR(E12-F12,"n/a") -> 0
A13: Volatility (per year) | B13: 0.15 | D13: Nest egg, 10th percentile ($) | E13: =B27 -> 451615.71 | F13: 451615.71 | G13: =IFERROR(E13-F13,"n/a") -> 0
A14: Random seed | B14: 42 | D14: Nest egg, 90th percentile ($) | E14: =B28 -> 1877929.6 | F14: 1877929.6 | G14: =IFERROR(E14-F14,"n/a") -> 0
D15: Median wealth at the end ($) | E15: =B29 -> 0 | F15: 0 | G15: =IFERROR(E15-F15,"n/a") -> 0
A16: Derived (formulas) | D16: Median year money runs out (failed paths) | E16: =B30 -> 38.666667 | F16: 38.666667 | G16: =IFERROR(E16-F16,"n/a") -> 0
A17: Monthly log drift (ln(1+r) - σ²/2) / 12 | B17: =(LN(1+B12)-B13^2/2)/12 -> 0.0047007207 | D17: First-year withdrawal rate | E17: =B31 -> 0.067479771 | F17: 0.067479771 | G17: =IFERROR(E17-F17,"n/a") -> 0
A18: Monthly log volatility σ / √12 | B18: =B13/SQRT(12) -> 0.04330127
A19: Median (typical) annual return | B19: =EXP(12*B17)-1 -> 0.058029958
A20: First-year withdrawal in retirement ($) | B20: =IF(B10=1,B9*(1+B11)^B7,B9) -> 60000
A21: Nest egg with no volatility ($) | B21: =FV((1+B12)^(1/12)-1,12*B7,-B6,-B5) -> 1054413.5
A23: Results (formulas over 'Simulations')
A24: Probability of success | B24: =AVERAGE(Simulations!$D$2:$D$10001) -> 0.3433
A25: Failed simulations | B25: =COUNTIF(Simulations!$D$2:$D$10001,0) -> 6567
A26: Median nest egg at retirement ($) | B26: =MEDIAN(Simulations!$B$2:$B$10001) -> 889155.36
A27: Nest egg, 10th percentile ($) | B27: =_xlfn.PERCENTILE.INC(Simulations!$B$2:$B$10001,0.1) -> 451615.71
A28: Nest egg, 90th percentile ($) | B28: =_xlfn.PERCENTILE.INC(Simulations!$B$2:$B$10001,0.9) -> 1877929.6
A29: Median wealth at the end ($) | B29: =MEDIAN(Simulations!$C$2:$C$10001) -> 0
A30: Median year money runs out (failed paths) | B30: =IFERROR(MEDIAN(Simulations!$E$2:$E$10001),"none") -> 38.666667
A31: First-year withdrawal rate | B31: =B20/B26 -> 0.067479771
A33: Notes
A34: Monthly steps. Saving: the balance grows, then the contribution is added (end of month).
A35: Retirement: 1/12 of the annual withdrawal is taken at the start of each month, then the rest grows.
A36: Withdrawals rise with inflation once a year. If 'today's money' = 1 they are first grown over the saving years.
A37: Success = every planned withdrawal is paid in full. A path fails in the first month it cannot pay.
A38: Returns: i.i.d. lognormal; the expected annual growth factor is 1 + r, the median is lower (volatility drag).
A39: Percentile paths are percentiles across simulations at each date, not the path of any one simulation.

Sheet Simulations
A1: Simulation | B1: Nest egg at retirement ($) | C1: Wealth at end ($) | D1: Success (1/0) | E1: Year money ran out
A2: 1 | B2: 910911.57 | C2: 0 | D2: 0 | E2: 40.916667
A3: 2 | B3: 1290237.2 | C3: 0 | D3: 0 | E3: 40.75
A4: 3 | B4: 561684.18 | C4: 0 | D4: 0 | E4: 38.75
A5: 4 | B5: 910407.49 | C5: 2519950.9 | D5: 1
A6: 5 | B6: 1279288.4 | C6: 553430.82 | D6: 1
A7: 6 | B7: 745110.03 | C7: 0 | D7: 0 | E7: 44.916667
A8: 7 | B8: 417436.63 | C8: 0 | D8: 0 | E8: 34.083333
A9: 8 | B9: 931805.63 | C9: 0 | D9: 0 | E9: 53.5
A10: 9 | B10: 2105842.2 | C10: 110505.88 | D10: 1
A11: 10 | B11: 846973.41 | C11: 0 | D11: 0 | E11: 36.083333
A12: 11 | B12: 764701.61 | C12: 0 | D12: 0 | E12: 40.916667
A13: 12 | B13: 1890415.9 | C13: 3399925.5 | D13: 1
A14: 13 | B14: 1221705.7 | C14: 0 | D14: 0 | E14: 47.833333
A15: 14 | B15: 868856.44 | C15: 0 | D15: 0 | E15: 47.083333
A16: 15 | B16: 578290.78 | C16: 0 | D16: 0 | E16: 31.666667
A17: 16 | B17: 1093633.7 | C17: 0 | D17: 0 | E17: 43.75
A18: 17 | B18: 964461.43 | C18: 190322.89 | D18: 1
A19: 18 | B19: 1430042.8 | C19: 0 | D19: 0 | E19: 46.25
A20: 19 | B20: 1435123.7 | C20: 2593429 | D20: 1
A21: 20 | B21: 4922705.4 | C21: 5939948.2 | D21: 1
A22: 21 | B22: 1718979.5 | C22: 1223010.3 | D22: 1
A23: 22 | B23: 741727.24 | C23: 0 | D23: 0 | E23: 42
A24: 23 | B24: 980513.2 | C24: 266783.35 | D24: 1
A25: 24 | B25: 358411.16 | C25: 0 | D25: 0 | E25: 32.166667
A26: 25 | B26: 928066.24 | C26: 22268643 | D26: 1
A27: 26 | B27: 1695442.1 | C27: 1550825.2 | D27: 1
A28: 27 | B28: 822980.17 | C28: 0 | D28: 0 | E28: 37.416667
A29: 28 | B29: 1863531 | C29: 1312676.4 | D29: 1
A30: 29 | B30: 264991.47 | C30: 0 | D30: 0 | E30: 29.166667
A31: 30 | B31: 841286.05 | C31: 0 | D31: 0 | E31: 41.583333
A32: 31 | B32: 807847.29 | C32: 0 | D32: 0 | E32: 48.833333
A33: 32 | B33: 1476133.4 | C33: 11265294 | D33: 1
A34: 33 | B34: 784791.42 | C34: 0 | D34: 0 | E34: 48.916667
A35: 34 | B35: 776470.31 | C35: 0 | D35: 0 | E35: 45.833333
A36: 35 | B36: 382092.46 | C36: 0 | D36: 0 | E36: 32.416667
A37: 36 | B37: 837641.2 | C37: 205422.89 | D37: 1
A38: 37 | B38: 1421539 | C38: 6241370 | D38: 1
A39: 38 | B39: 1382593.2 | C39: 6528464 | D39: 1
A40: 39 | B40: 1006216.8 | C40: 0 | D40: 0 | E40: 41.416667
...

Sheet Withdrawals
A1: Retirement year | B1: Years from today | C1: Annual withdrawal ($) | D1: Monthly withdrawal ($) | E1: In today's money ($)
A2: 1 | B2: =Summary!$B$7+A2 -> 26 | C2: =Summary!$B$20*(1+Summary!$B$11)^(A2-1) -> 60000 | D2: =C2/12 -> 5000 | E2: =C2/(1+Summary!$B$11)^(B2-1) -> 32363.435
A3: 2 | B3: =Summary!$B$7+A3 -> 27 | C3: =Summary!$B$20*(1+Summary!$B$11)^(A3-1) -> 61500 | D3: =C3/12 -> 5125 | E3: =C3/(1+Summary!$B$11)^(B3-1) -> 32363.435
A4: 3 | B4: =Summary!$B$7+A4 -> 28 | C4: =Summary!$B$20*(1+Summary!$B$11)^(A4-1) -> 63037.5 | D4: =C4/12 -> 5253.125 | E4: =C4/(1+Summary!$B$11)^(B4-1) -> 32363.435
A5: 4 | B5: =Summary!$B$7+A5 -> 29 | C5: =Summary!$B$20*(1+Summary!$B$11)^(A5-1) -> 64613.438 | D5: =C5/12 -> 5384.4531 | E5: =C5/(1+Summary!$B$11)^(B5-1) -> 32363.435
A6: 5 | B6: =Summary!$B$7+A6 -> 30 | C6: =Summary!$B$20*(1+Summary!$B$11)^(A6-1) -> 66228.773 | D6: =C6/12 -> 5519.0645 | E6: =C6/(1+Summary!$B$11)^(B6-1) -> 32363.435
A7: 6 | B7: =Summary!$B$7+A7 -> 31 | C7: =Summary!$B$20*(1+Summary!$B$11)^(A7-1) -> 67884.493 | D7: =C7/12 -> 5657.0411 | E7: =C7/(1+Summary!$B$11)^(B7-1) -> 32363.435
A8: 7 | B8: =Summary!$B$7+A8 -> 32 | C8: =Summary!$B$20*(1+Summary!$B$11)^(A8-1) -> 69581.605 | D8: =C8/12 -> 5798.4671 | E8: =C8/(1+Summary!$B$11)^(B8-1) -> 32363.435
A9: 8 | B9: =Summary!$B$7+A9 -> 33 | C9: =Summary!$B$20*(1+Summary!$B$11)^(A9-1) -> 71321.145 | D9: =C9/12 -> 5943.4288 | E9: =C9/(1+Summary!$B$11)^(B9-1) -> 32363.435
A10: 9 | B10: =Summary!$B$7+A10 -> 34 | C10: =Summary!$B$20*(1+Summary!$B$11)^(A10-1) -> 73104.174 | D10: =C10/12 -> 6092.0145 | E10: =C10/(1+Summary!$B$11)^(B10-1) -> 32363.435
A11: 10 | B11: =Summary!$B$7+A11 -> 35 | C11: =Summary!$B$20*(1+Summary!$B$11)^(A11-1) -> 74931.778 | D11: =C11/12 -> 6244.3148 | E11: =C11/(1+Summary!$B$11)^(B11-1) -> 32363.435
A12: 11 | B12: =Summary!$B$7+A12 -> 36 | C12: =Summary!$B$20*(1+Summary!$B$11)^(A12-1) -> 76805.073 | D12: =C12/12 -> 6400.4227 | E12: =C12/(1+Summary!$B$11)^(B12-1) -> 32363.435
A13: 12 | B13: =Summary!$B$7+A13 -> 37 | C13: =Summary!$B$20*(1+Summary!$B$11)^(A13-1) -> 78725.199 | D13: =C13/12 -> 6560.4333 | E13: =C13/(1+Summary!$B$11)^(B13-1) -> 32363.435
... A31: 30 | B31: =Summary!$B$7+A31 -> 55 | C31: =Summary!$B$20*(1+Summary!$B$11)^(A31-1) -> 122784.44 | D31: =C31/12 -> 10232.037 | E31: =C31/(1+Summary!$B$11)^(B31-1) -> 32363.435

Sheet Percentiles by Year
A1: Year | B1: Phase | C1: P5 | D1: P25 | E1: Median | F1: P75 | G1: P95 | H1: Median in today's money
A2: 0 | B2: Saving | C2: 50000 | D2: 50000 | E2: 50000 | F2: 50000 | G2: 50000 | H2: 50000
A3: 1 | B3: Saving | C3: 52390.82 | D3: 59567.61 | E3: 65106.31 | F3: 71209.09 | G3: 81698.52 | H3: 63518.35
A4: 2 | B4: Saving | C4: 61306.66 | D4: 72389.52 | E4: 81336.44 | F4: 91750.36 | G4: 109942.67 | H4: 77417.19
A5: 3 | B5: Saving | C5: 70549.3 | D5: 85768.38 | E5: 98607.77 | F5: 113532.62 | G5: 140667.49 | H5: 91567.12
A6: 4 | B6: Saving | C6: 80092.28 | D6: 100011.24 | E6: 116622.26 | F6: 137035.8 | G6: 174029.03 | H6: 105654.01
A7: 5 | B7: Saving | C7: 89836.22 | D7: 114348.22 | E7: 135226.14 | F7: 161793.97 | G7: 210334.85 | H7: 119520.21
A8: 6 | B8: Saving | C8: 100773.21 | D8: 130157.98 | E8: 155888.73 | F8: 188156.78 | G8: 249431.21 | H8: 134422.36
A9: 7 | B9: Saving | C9: 111785.27 | D9: 146562.52 | E9: 177937.77 | F9: 217947.72 | G9: 292373.93 | H9: 149692.86
A10: 8 | B10: Saving | C10: 122711.47 | D10: 163607 | E10: 201457.76 | F10: 249577.32 | G10: 341007.6 | H10: 165345.76
A11: 9 | B11: Saving | C11: 134418.52 | D11: 181562.97 | E11: 225989.54 | F11: 283404.15 | G11: 397642.46 | H11: 180956.23
A12: 10 | B12: Saving | C12: 145537.65 | D12: 200590.26 | E12: 251873.94 | F12: 319448.71 | G12: 454772.85 | H12: 196763.52
A13: 11 | B13: Saving | C13: 158577.68 | D13: 219981.26 | E13: 280487.42 | F13: 358213.67 | G13: 520183.87 | H13: 213772.02
... A57: 55 | B57: Retirement | C57: 0 | D57: 0 | E57: 0 | F57: 1380278.2 | G57: 12757755 | H57: 0

Sheet Withdrawal Rates
A1: Success of an x% initial withdrawal (raised with inflation) over 30 years
A2: Nest egg at retirement used ($) | B2: 869767.91
A4: Initial withdrawal rate | B4: First-year withdrawal ($) | C4: Probability of success
A5: 0.02 | B5: =A5*$B$2 -> 17395.358 | C5: 0.972
A6: 0.025 | B6: =A6*$B$2 -> 21744.198 | C6: 0.9345
A7: 0.03 | B7: =A7*$B$2 -> 26093.037 | C7: 0.868
A8: 0.035 | B8: =A8*$B$2 -> 30441.877 | C8: 0.787
A9: 0.04 | B9: =A9*$B$2 -> 34790.717 | C9: 0.6865
A10: 0.045 | B10: =A10*$B$2 -> 39139.556 | C10: 0.5935
A11: 0.05 | B11: =A11*$B$2 -> 43488.396 | C11: 0.499
A12: 0.055 | B12: =A12*$B$2 -> 47837.235 | C12: 0.404
A13: 0.06 | B13: =A13*$B$2 -> 52186.075 | C13: 0.3255
A14: 0.065 | B14: =A14*$B$2 -> 56534.914 | C14: 0.2585
A15: 0.07 | B15: =A15*$B$2 -> 60883.754 | C15: 0.203
A16: 0.075 | B16: =A16*$B$2 -> 65232.594 | C16: 0.155
A17: 0.08 | B17: =A17*$B$2 -> 69581.433 | C17: 0.124
