Workbook

Sheet Summary
A1: Apple Inc. (AAPL) - Financial Statement Analysis
A2: Sector: Technology | Industry: Consumer Electronics | Currency: USD | Latest fiscal year: FY2025
A4: Key metrics (live links to the analysis sheets)
A5: Metric | B5: FY2022 | C5: FY2023 | D5: FY2024 | E5: FY2025
A6: Revenue (millions) | B6: ='Income Statement'!B4 | C6: ='Income Statement'!C4 | D6: ='Income Statement'!D4 | E6: ='Income Statement'!E4
A7: Net Income (millions) | B7: ='Income Statement'!B12 | C7: ='Income Statement'!C12 | D7: ='Income Statement'!D12 | E7: ='Income Statement'!E12
A8: Gross Margin | B8: ='Ratios'!B9 | C8: ='Ratios'!C9 | D8: ='Ratios'!D9 | E8: ='Ratios'!E9
A9: Operating Margin | B9: ='Ratios'!B10 | C9: ='Ratios'!C10 | D9: ='Ratios'!D10 | E9: ='Ratios'!E10
A10: Net Profit Margin | B10: ='Ratios'!B11 | C10: ='Ratios'!C11 | D10: ='Ratios'!D11 | E10: ='Ratios'!E11
A11: Return on Equity (ROE) | B11: ='Ratios'!B15 | C11: ='Ratios'!C15 | D11: ='Ratios'!D15 | E11: ='Ratios'!E15
A12: Return on Invested Capital (ROIC) | B12: ='Ratios'!B17 | C12: ='Ratios'!C17 | D12: ='Ratios'!D17 | E12: ='Ratios'!E17
A13: Current Ratio | B13: ='Ratios'!B5 | C13: ='Ratios'!C5 | D13: ='Ratios'!D5 | E13: ='Ratios'!E5
A14: Debt-to-Equity | B14: ='Ratios'!B19 | C14: ='Ratios'!C19 | D14: ='Ratios'!D19 | E14: ='Ratios'!E19
A15: Interest Coverage | B15: ='Ratios'!B22 | C15: ='Ratios'!C22 | D15: ='Ratios'!D22 | E15: ='Ratios'!E22
A16: Cash Conversion Cycle (CCC) | B16: ='Ratios'!B31 | C16: ='Ratios'!C31 | D16: ='Ratios'!D31 | E16: ='Ratios'!E31
A17: Free Cash Flow | B17: ='Ratios'!B34 | C17: ='Ratios'!C34 | D17: ='Ratios'!D34 | E17: ='Ratios'!E34
A18: FCF Margin | B18: ='Ratios'!B35 | C18: ='Ratios'!C35 | D18: ='Ratios'!D35 | E18: ='Ratios'!E35
A19: Altman Z-Score | B19: ='Altman Z'!B11 | C19: ='Altman Z'!C11 | D19: ='Altman Z'!D11 | E19: ='Altman Z'!E11
A20: Zone (Original) | B20: ='Altman Z'!B12 | C20: ='Altman Z'!C12 | D20: ='Altman Z'!D12 | E20: ='Altman Z'!E12
A21: Altman Z''-Score (Non-Mfg) | B21: ='Altman Z'!B13 | C21: ='Altman Z'!C13 | D21: ='Altman Z'!D13 | E21: ='Altman Z'!E13
A22: Total Piotroski F-Score | B22: ='Piotroski'!B22 | C22: ='Piotroski'!C22 | D22: ='Piotroski'!D22 | E22: ='Piotroski'!E22
A24: Rule-based assessment for FY2025: Very Strong
A25: Apple Inc. shows strong fundamentals in FY2025: no red flags and 6 clear strengths.
A27: Strengths (6)
A28: + High free-cash-flow margin (23.7%): Free cash flow was 23.7% of revenue, leaving cash for dividends, buybacks or debt repayment.
A29: + Altman Z in the safe zone (10.17): Altman Z of 10.17 is above the 2.99 safe threshold: low statistical bankruptcy risk.
A30: + High return on equity (151.9%): Net income was 151.9% of year-end shareholders' equity.
A31: + High ROIC (65.1%): After-tax operating profit was 65.1% of debt + equity, well above a typical 8-10% cost of capital.
A32: + Wide operating margin (32.0%): The company keeps 32.0 cents of operating profit from each unit of revenue.
A33: + Piotroski F-score 8/9: Profitability, balance sheet and efficiency nearly all improved versus last year.
A35: To monitor (1)
A36: - Current ratio below 1 (0.89x): Current liabilities are larger than current assets (0.89x). Fine for firms with strong cash flow and bargaining power, risky otherwise.
A38: Red flags (0)
... A42: The findings text is produced by the Python rules at export time; every number above is a formula. Educational project, not investment advice.

Sheet Income Statement
A1: Apple Inc. (AAPL) - Income Statement
A2: USD millions, except per-share data. Blue = input from the source data; black = formula. Blank = not reported.
A3: Line item | B3: FY2022 | C3: FY2023 | D3: FY2024 | E3: FY2025
A4: Total Revenue | B4: 394328 | C4: 383285 | D4: 391035 | E4: 416161
A5: Cost of Revenue (COGS) | B5: 223546 | C5: 214137 | D5: 210352 | E5: 220960
A6: Gross Profit | B6: 170782 | C6: 169148 | D6: 180683 | E6: 195201
A7: Operating Expenses | B7: 51345 | C7: 54847 | D7: 57467 | E7: 62151
A8: Operating Income (EBIT) | B8: 119437 | C8: 114301 | D8: 123216 | E8: 133050
A9: Interest Expense | B9: 2931 | C9: 3933
A10: Pre-tax Income (EBT) | B10: 119103 | C10: 113736 | D10: 123485 | E10: 132729
A11: Income Tax Expense | B11: 19300 | C11: 16741 | D11: 29749 | E11: 20719
A12: Net Income | B12: 99803 | C12: 96995 | D12: 93736 | E12: 112010
A13: Diluted EPS | B13: 6.11 | C13: 6.13 | D13: 6.08 | E13: 7.46
A14: Diluted Average Shares (millions) | B14: 16325.819 | C14: 15812.547 | D14: 15408.095 | E14: 15004.697

Sheet Balance Sheet
A1: Apple Inc. (AAPL) - Balance Sheet
A2: USD millions, except per-share data. Blue = input from the source data; black = formula. Blank = not reported.
A3: Line item | B3: FY2022 | C3: FY2023 | D3: FY2024 | E3: FY2025
A4: Cash and Cash Equivalents | B4: 23646 | C4: 29965 | D4: 29943 | E4: 35934
A5: Short-Term Investments | B5: 24658 | C5: 31590 | D5: 35228 | E5: 18763
A6: Cash + Short-Term Investments | B6: 48304 | C6: 61555 | D6: 65171 | E6: 54697
A7: Total Receivables | B7: 60932 | C7: 60985 | D7: 66243 | E7: 72957
A8: Accounts Receivable (trade) | B8: 28184 | C8: 29508 | D8: 33410 | E8: 39777
A9: Inventory | B9: 4946 | C9: 6331 | D9: 7286 | E9: 5718
A10: Total Current Assets | B10: 135405 | C10: 143566 | D10: 152987 | E10: 147957
A11: Net PP&E | B11: 42117 | C11: 43715 | D11: 45680 | E11: 49834
A12: Goodwill and Intangibles
A13: Total Assets | B13: 352755 | C13: 352583 | D13: 364980 | E13: 359241
A14: Accounts Payable | B14: 64115 | C14: 62611 | D14: 68960 | E14: 69860
A15: Current Debt (incl. leases) | B15: 22773 | C15: 15807 | D15: 20879 | E15: 20329
A16: Total Current Liabilities | B16: 153982 | C16: 145308 | D16: 176392 | E16: 165631
A17: Long-Term Debt (incl. leases) | B17: 109707 | C17: 95281 | D17: 85750 | E17: 78328
A18: Total Debt | B18: 132480 | C18: 111088 | D18: 106629 | E18: 98657
A19: Total Liabilities | B19: 302083 | C19: 290437 | D19: 308030 | E19: 285508
A20: Retained Earnings | B20: -3068 | C20: -214 | D20: -19154 | E20: -14264
A21: Shareholders' Equity | B21: 50672 | C21: 62146 | D21: 56950 | E21: 73733
A22: Working Capital (CA - CL) | B22: =B10-B16 | C22: =C10-C16 | D22: =D10-D16 | E22: =E10-E16
A23: Shares Outstanding (millions) | B23: 15943.425 | C23: 15550.061 | D23: 15116.786 | E23: 14773.26
A25: Market data (not part of the balance sheet)
A26: Share price at fiscal year end | B26: 138.2 | C26: 171.21001 | D26: 233 | E26: 254.63
A27: Market Value of Equity (price x shares) | B27: ='Balance Sheet'!B26*'Balance Sheet'!B23 | C27: ='Balance Sheet'!C26*'Balance Sheet'!C23 | D27: ='Balance Sheet'!D26*'Balance Sheet'!D23 | E27: ='Balance Sheet'!E26*'Balance Sheet'!E23
A29: Price = last close on/before the balance-sheet date (Yahoo Finance). Shares = year-end shares outstanding.

Sheet Cash Flow
A1: Apple Inc. (AAPL) - Cash Flow
A2: USD millions, except per-share data. Blue = input from the source data; black = formula. Blank = not reported.
A3: Line item | B3: FY2022 | C3: FY2023 | D3: FY2024 | E3: FY2025
A4: Operating Cash Flow (CFO) | B4: 122151 | C4: 110543 | D4: 118254 | E4: 111482
A5: Capital Expenditure (as reported) | B5: -10708 | C5: -10959 | D5: -9447 | E5: -12715
A6: Free Cash Flow (CFO - |Capex|) | B6: =B4-ABS(B5) | C6: =C4-ABS(C5) | D6: =D4-ABS(D5) | E6: =E4-ABS(E5)
A7: Investing Cash Flow | B7: -22354 | C7: 3705 | D7: 2935 | E7: 15195
A8: Financing Cash Flow | B8: -110749 | C8: -108488 | D8: -121983 | E8: -120686
A9: Depreciation & Amortization | B9: 11104 | C9: 11519 | D9: 11445 | E9: 11698
A10: Dividends Paid | B10: -14841 | C10: -15025 | D10: -15234 | E10: -15421
A11: Share Repurchases | B11: -89402 | C11: -77550 | D11: -94949 | E11: -90711

Sheet Ratios
A1: Apple Inc. (AAPL) - Financial Ratios
A2: Every cell is a live formula on the statement sheets. Ending balances unless the label says 'avg.'; days use 365.
A3: Ratio | B3: FY2022 | C3: FY2023 | D3: FY2024 | E3: FY2025
A4: 1. Liquidity
A5: Current Ratio | B5: =IF(COUNT('Balance Sheet'!B10,'Balance Sheet'!B16)<2,"n/a",IFERROR('Balance Sheet'!B10/'Balance Sheet'!B16,"n/a")) | C5: =IF(COUNT('Balance Sheet'!C10,'Balance Sheet'!C16)<2,"n/a",IFERROR('Balance Sheet'!C10/'Balance Sheet'!C16,"n/a")) | D5: =IF(COUNT('Balance Sheet'!D10,'Balance Sheet'!D16)<2,"n/a",IFERROR('Balance Sheet'!D10/'Balance Sheet'!D16,"n/a")) | E5: =IF(COUNT('Balance Sheet'!E10,'Balance Sheet'!E16)<2,"n/a",IFERROR('Balance Sheet'!E10/'Balance Sheet'!E16,"n/a")) | F5: Current assets / current liabilities
A6: Quick Ratio | B6: =IF(COUNT('Balance Sheet'!B6,'Balance Sheet'!B7,'Balance Sheet'!B16)<3,"n/a",IFERROR(('Balance Sheet'!B6+'Balance Sheet'!B7)/'Balance Sheet'!B16,"n/a")) | C6: =IF(COUNT('Balance Sheet'!C6,'Balance Sheet'!C7,'Balance Sheet'!C16)<3,"n/a",IFERROR(('Balance Sheet'!C6+'Balance Sheet'!C7)/'Balance Sheet'!C16,"n/a")) | D6: =IF(COUNT('Balance Sheet'!D6,'Balance Sheet'!D7,'Balance Sheet'!D16)<3,"n/a",IFERROR(('Balance Sheet'!D6+'Balance Sheet'!D7)/'Balance Sheet'!D16,"n/a")) | E6: =IF(COUNT('Balance Sheet'!E6,'Balance Sheet'!E7,'Balance Sheet'!E16)<3,"n/a",IFERROR(('Balance Sheet'!E6+'Balance Sheet'!E7)/'Balance Sheet'!E16,"n/a")) | F6: (Cash + ST investments + receivables) / CL
A7: Cash Ratio | B7: =IF(COUNT('Balance Sheet'!B6,'Balance Sheet'!B16)<2,"n/a",IFERROR('Balance Sheet'!B6/'Balance Sheet'!B16,"n/a")) | C7: =IF(COUNT('Balance Sheet'!C6,'Balance Sheet'!C16)<2,"n/a",IFERROR('Balance Sheet'!C6/'Balance Sheet'!C16,"n/a")) | D7: =IF(COUNT('Balance Sheet'!D6,'Balance Sheet'!D16)<2,"n/a",IFERROR('Balance Sheet'!D6/'Balance Sheet'!D16,"n/a")) | E7: =IF(COUNT('Balance Sheet'!E6,'Balance Sheet'!E16)<2,"n/a",IFERROR('Balance Sheet'!E6/'Balance Sheet'!E16,"n/a")) | F7: (Cash + ST investments) / CL
A8: 2. Profitability
A9: Gross Margin | B9: =IF(COUNT('Income Statement'!B6,'Income Statement'!B4)<2,"n/a",IFERROR('Income Statement'!B6/'Income Statement'!B4,"n/a")) | C9: =IF(COUNT('Income Statement'!C6,'Income Statement'!C4)<2,"n/a",IFERROR('Income Statement'!C6/'Income Statement'!C4,"n/a")) | D9: =IF(COUNT('Income Statement'!D6,'Income Statement'!D4)<2,"n/a",IFERROR('Income Statement'!D6/'Income Statement'!D4,"n/a")) | E9: =IF(COUNT('Income Statement'!E6,'Income Statement'!E4)<2,"n/a",IFERROR('Income Statement'!E6/'Income Statement'!E4,"n/a")) | F9: Gross profit / revenue
A10: Operating Margin | B10: =IF(COUNT('Income Statement'!B8,'Income Statement'!B4)<2,"n/a",IFERROR('Income Statement'!B8/'Income Statement'!B4,"n/a")) | C10: =IF(COUNT('Income Statement'!C8,'Income Statement'!C4)<2,"n/a",IFERROR('Income Statement'!C8/'Income Statement'!C4,"n/a")) | D10: =IF(COUNT('Income Statement'!D8,'Income Statement'!D4)<2,"n/a",IFERROR('Income Statement'!D8/'Income Statement'!D4,"n/a")) | E10: =IF(COUNT('Income Statement'!E8,'Income Statement'!E4)<2,"n/a",IFERROR('Income Statement'!E8/'Income Statement'!E4,"n/a")) | F10: Operating income / revenue
A11: Net Profit Margin | B11: =IF(COUNT('Income Statement'!B12,'Income Statement'!B4)<2,"n/a",IFERROR('Income Statement'!B12/'Income Statement'!B4,"n/a")) | C11: =IF(COUNT('Income Statement'!C12,'Income Statement'!C4)<2,"n/a",IFERROR('Income Statement'!C12/'Income Statement'!C4,"n/a")) | D11: =IF(COUNT('Income Statement'!D12,'Income Statement'!D4)<2,"n/a",IFERROR('Income Statement'!D12/'Income Statement'!D4,"n/a")) | E11: =IF(COUNT('Income Statement'!E12,'Income Statement'!E4)<2,"n/a",IFERROR('Income Statement'!E12/'Income Statement'!E4,"n/a")) | F11: Net income / revenue
A12: Effective Tax Rate | B12: =IF(COUNT('Income Statement'!B10,'Income Statement'!B11)<2,"n/a",IFERROR(IF('Income Statement'!B10<=0,0,IF(AND('Income Statement'!B11/'Income Statement'!B10>=0,'Income Statement'!B11/'Income Statement'!B10<=1),'Income Statement'!B11/'Income Statement'!B10,"n/a")),"n/a")) | C12: =IF(COUNT('Income Statement'!C10,'Income Statement'!C11)<2,"n/a",IFERROR(IF('Income Statement'!C10<=0,0,IF(AND('Income Statement'!C11/'Income Statement'!C10>=0,'Income Statement'!C11/'Income Statement'!C10<=1),'Income Statement'!C11/'Income Statement'!C10,"n/a")),"n/a")) | D12: =IF(COUNT('Income Statement'!D10,'Income Statement'!D11)<2,"n/a",IFERROR(IF('Income Statement'!D10<=0,0,IF(AND('Income Statement'!D11/'Income Statement'!D10>=0,'Income Statement'!D11/'Income Statement'!D10<=1),'Income Statement'!D11/'Income Statement'!D10,"n/a")),"n/a")) | E12: =IF(COUNT('Income Statement'!E10,'Income Statement'!E11)<2,"n/a",IFERROR(IF('Income Statement'!E10<=0,0,IF(AND('Income Statement'!E11/'Income Statement'!E10>=0,'Income Statement'!E11/'Income Statement'!E10<=1),'Income Statement'!E11/'Income Statement'!E10,"n/a")),"n/a")) | F12: Tax / pre-tax income (0% if pre-tax <= 0)
A13: Return on Assets (ROA) | B13: =IF(COUNT('Income Statement'!B12,'Balance Sheet'!B13)<2,"n/a",IFERROR('Income Statement'!B12/'Balance Sheet'!B13,"n/a")) | C13: =IF(COUNT('Income Statement'!C12,'Balance Sheet'!C13)<2,"n/a",IFERROR('Income Statement'!C12/'Balance Sheet'!C13,"n/a")) | D13: =IF(COUNT('Income Statement'!D12,'Balance Sheet'!D13)<2,"n/a",IFERROR('Income Statement'!D12/'Balance Sheet'!D13,"n/a")) | E13: =IF(COUNT('Income Statement'!E12,'Balance Sheet'!E13)<2,"n/a",IFERROR('Income Statement'!E12/'Balance Sheet'!E13,"n/a")) | F13: NI / ending total assets
A14: ROA (avg. assets) | B14: n/a | C14: =IF(COUNT('Income Statement'!C12,'Balance Sheet'!C13,'Balance Sheet'!B13)<3,"n/a",IFERROR('Income Statement'!C12/AVERAGE('Balance Sheet'!C13,'Balance Sheet'!B13),"n/a")) | D14: =IF(COUNT('Income Statement'!D12,'Balance Sheet'!D13,'Balance Sheet'!C13)<3,"n/a",IFERROR('Income Statement'!D12/AVERAGE('Balance Sheet'!D13,'Balance Sheet'!C13),"n/a")) | E14: =IF(COUNT('Income Statement'!E12,'Balance Sheet'!E13,'Balance Sheet'!D13)<3,"n/a",IFERROR('Income Statement'!E12/AVERAGE('Balance Sheet'!E13,'Balance Sheet'!D13),"n/a")) | F14: NI / average total assets
A15: Return on Equity (ROE) | B15: =IF(COUNT('Income Statement'!B12,'Balance Sheet'!B21)<2,"n/a",IFERROR('Income Statement'!B12/'Balance Sheet'!B21,"n/a")) | C15: =IF(COUNT('Income Statement'!C12,'Balance Sheet'!C21)<2,"n/a",IFERROR('Income Statement'!C12/'Balance Sheet'!C21,"n/a")) | D15: =IF(COUNT('Income Statement'!D12,'Balance Sheet'!D21)<2,"n/a",IFERROR('Income Statement'!D12/'Balance Sheet'!D21,"n/a")) | E15: =IF(COUNT('Income Statement'!E12,'Balance Sheet'!E21)<2,"n/a",IFERROR('Income Statement'!E12/'Balance Sheet'!E21,"n/a")) | F15: NI / ending equity
A16: ROE (avg. equity) | B16: n/a | C16: =IF(COUNT('Income Statement'!C12,'Balance Sheet'!C21,'Balance Sheet'!B21)<3,"n/a",IFERROR('Income Statement'!C12/AVERAGE('Balance Sheet'!C21,'Balance Sheet'!B21),"n/a")) | D16: =IF(COUNT('Income Statement'!D12,'Balance Sheet'!D21,'Balance Sheet'!C21)<3,"n/a",IFERROR('Income Statement'!D12/AVERAGE('Balance Sheet'!D21,'Balance Sheet'!C21),"n/a")) | E16: =IF(COUNT('Income Statement'!E12,'Balance Sheet'!E21,'Balance Sheet'!D21)<3,"n/a",IFERROR('Income Statement'!E12/AVERAGE('Balance Sheet'!E21,'Balance Sheet'!D21),"n/a")) | F16: NI / average equity
A17: Return on Invested Capital (ROIC) | B17: =IF(COUNT('Income Statement'!B8,'Ratios'!B12,'Balance Sheet'!B18,'Balance Sheet'!B21)<4,"n/a",IFERROR(IF('Balance Sheet'!B18+'Balance Sheet'!B21<=0,"n/a",'Income Statement'!B8*(1-'Ratios'!B12)/('Balance Sheet'!B18+'Balance Sheet'!B21)),"n/a")) | C17: =IF(COUNT('Income Statement'!C8,'Ratios'!C12,'Balance Sheet'!C18,'Balance Sheet'!C21)<4,"n/a",IFERROR(IF('Balance Sheet'!C18+'Balance Sheet'!C21<=0,"n/a",'Income Statement'!C8*(1-'Ratios'!C12)/('Balance Sheet'!C18+'Balance Sheet'!C21)),"n/a")) | D17: =IF(COUNT('Income Statement'!D8,'Ratios'!D12,'Balance Sheet'!D18,'Balance Sheet'!D21)<4,"n/a",IFERROR(IF('Balance Sheet'!D18+'Balance Sheet'!D21<=0,"n/a",'Income Statement'!D8*(1-'Ratios'!D12)/('Balance Sheet'!D18+'Balance Sheet'!D21)),"n/a")) | E17: =IF(COUNT('Income Statement'!E8,'Ratios'!E12,'Balance Sheet'!E18,'Balance Sheet'!E21)<4,"n/a",IFERROR(IF('Balance Sheet'!E18+'Balance Sheet'!E21<=0,"n/a",'Income Statement'!E8*(1-'Ratios'!E12)/('Balance Sheet'!E18+'Balance Sheet'!E21)),"n/a")) | F17: EBIT x (1 - tax rate) / (total debt + equity)
A18: 3. Solvency & leverage
A19: Debt-to-Equity | B19: =IF(COUNT('Balance Sheet'!B18,'Balance Sheet'!B21)<2,"n/a",IFERROR('Balance Sheet'!B18/'Balance Sheet'!B21,"n/a")) | C19: =IF(COUNT('Balance Sheet'!C18,'Balance Sheet'!C21)<2,"n/a",IFERROR('Balance Sheet'!C18/'Balance Sheet'!C21,"n/a")) | D19: =IF(COUNT('Balance Sheet'!D18,'Balance Sheet'!D21)<2,"n/a",IFERROR('Balance Sheet'!D18/'Balance Sheet'!D21,"n/a")) | E19: =IF(COUNT('Balance Sheet'!E18,'Balance Sheet'!E21)<2,"n/a",IFERROR('Balance Sheet'!E18/'Balance Sheet'!E21,"n/a")) | F19: Total debt / equity
A20: Debt-to-Assets | B20: =IF(COUNT('Balance Sheet'!B18,'Balance Sheet'!B13)<2,"n/a",IFERROR('Balance Sheet'!B18/'Balance Sheet'!B13,"n/a")) | C20: =IF(COUNT('Balance Sheet'!C18,'Balance Sheet'!C13)<2,"n/a",IFERROR('Balance Sheet'!C18/'Balance Sheet'!C13,"n/a")) | D20: =IF(COUNT('Balance Sheet'!D18,'Balance Sheet'!D13)<2,"n/a",IFERROR('Balance Sheet'!D18/'Balance Sheet'!D13,"n/a")) | E20: =IF(COUNT('Balance Sheet'!E18,'Balance Sheet'!E13)<2,"n/a",IFERROR('Balance Sheet'!E18/'Balance Sheet'!E13,"n/a")) | F20: Total debt / total assets
A21: Financial Leverage (Multiplier) | B21: =IF(COUNT('Balance Sheet'!B13,'Balance Sheet'!B21)<2,"n/a",IFERROR('Balance Sheet'!B13/'Balance Sheet'!B21,"n/a")) | C21: =IF(COUNT('Balance Sheet'!C13,'Balance Sheet'!C21)<2,"n/a",IFERROR('Balance Sheet'!C13/'Balance Sheet'!C21,"n/a")) | D21: =IF(COUNT('Balance Sheet'!D13,'Balance Sheet'!D21)<2,"n/a",IFERROR('Balance Sheet'!D13/'Balance Sheet'!D21,"n/a")) | E21: =IF(COUNT('Balance Sheet'!E13,'Balance Sheet'!E21)<2,"n/a",IFERROR('Balance Sheet'!E13/'Balance Sheet'!E21,"n/a")) | F21: Total assets / equity
A22: Interest Coverage | B22: =IF(COUNT('Income Statement'!B8,'Income Statement'!B9)<2,"n/a",IFERROR('Income Statement'!B8/ABS('Income Statement'!B9),"n/a")) | C22: =IF(COUNT('Income Statement'!C8,'Income Statement'!C9)<2,"n/a",IFERROR('Income Statement'!C8/ABS('Income Statement'!C9),"n/a")) | D22: =IF(COUNT('Income Statement'!D8,'Income Statement'!D9)<2,"n/a",IFERROR('Income Statement'!D8/ABS('Income Statement'!D9),"n/a")) | E22: =IF(COUNT('Income Statement'!E8,'Income Statement'!E9)<2,"n/a",IFERROR('Income Statement'!E8/ABS('Income Statement'!E9),"n/a")) | F22: Operating income / |interest expense|
A23: 4. Efficiency & working capital (365-day year)
A24: Asset Turnover | B24: =IF(COUNT('Income Statement'!B4,'Balance Sheet'!B13)<2,"n/a",IFERROR('Income Statement'!B4/'Balance Sheet'!B13,"n/a")) | C24: =IF(COUNT('Income Statement'!C4,'Balance Sheet'!C13)<2,"n/a",IFERROR('Income Statement'!C4/'Balance Sheet'!C13,"n/a")) | D24: =IF(COUNT('Income Statement'!D4,'Balance Sheet'!D13)<2,"n/a",IFERROR('Income Statement'!D4/'Balance Sheet'!D13,"n/a")) | E24: =IF(COUNT('Income Statement'!E4,'Balance Sheet'!E13)<2,"n/a",IFERROR('Income Statement'!E4/'Balance Sheet'!E13,"n/a")) | F24: Revenue / ending total assets
A25: Asset Turnover (avg. assets) | B25: n/a | C25: =IF(COUNT('Income Statement'!C4,'Balance Sheet'!C13,'Balance Sheet'!B13)<3,"n/a",IFERROR('Income Statement'!C4/AVERAGE('Balance Sheet'!C13,'Balance Sheet'!B13),"n/a")) | D25: =IF(COUNT('Income Statement'!D4,'Balance Sheet'!D13,'Balance Sheet'!C13)<3,"n/a",IFERROR('Income Statement'!D4/AVERAGE('Balance Sheet'!D13,'Balance Sheet'!C13),"n/a")) | E25: =IF(COUNT('Income Statement'!E4,'Balance Sheet'!E13,'Balance Sheet'!D13)<3,"n/a",IFERROR('Income Statement'!E4/AVERAGE('Balance Sheet'!E13,'Balance Sheet'!D13),"n/a")) | F25: Revenue / average total assets
A26: Inventory Turnover | B26: =IF(COUNT('Income Statement'!B5,'Balance Sheet'!B9)<2,"n/a",IFERROR(IF('Balance Sheet'!B9<=0,"n/a",'Income Statement'!B5/'Balance Sheet'!B9),"n/a")) | C26: =IF(COUNT('Income Statement'!C5,'Balance Sheet'!C9)<2,"n/a",IFERROR(IF('Balance Sheet'!C9<=0,"n/a",'Income Statement'!C5/'Balance Sheet'!C9),"n/a")) | D26: =IF(COUNT('Income Statement'!D5,'Balance Sheet'!D9)<2,"n/a",IFERROR(IF('Balance Sheet'!D9<=0,"n/a",'Income Statement'!D5/'Balance Sheet'!D9),"n/a")) | E26: =IF(COUNT('Income Statement'!E5,'Balance Sheet'!E9)<2,"n/a",IFERROR(IF('Balance Sheet'!E9<=0,"n/a",'Income Statement'!E5/'Balance Sheet'!E9),"n/a")) | F26: COGS / ending inventory
A27: Inventory Turnover (avg. inventory) | B27: n/a | C27: =IF(COUNT('Income Statement'!C5,'Balance Sheet'!C9,'Balance Sheet'!B9)<3,"n/a",IFERROR('Income Statement'!C5/AVERAGE('Balance Sheet'!C9,'Balance Sheet'!B9),"n/a")) | D27: =IF(COUNT('Income Statement'!D5,'Balance Sheet'!D9,'Balance Sheet'!C9)<3,"n/a",IFERROR('Income Statement'!D5/AVERAGE('Balance Sheet'!D9,'Balance Sheet'!C9),"n/a")) | E27: =IF(COUNT('Income Statement'!E5,'Balance Sheet'!E9,'Balance Sheet'!D9)<3,"n/a",IFERROR('Income Statement'!E5/AVERAGE('Balance Sheet'!E9,'Balance Sheet'!D9),"n/a")) | F27: COGS / average inventory
A28: Days Sales Outstanding (DSO) | B28: =IF(COUNT('Balance Sheet'!B8,'Income Statement'!B4)<2,"n/a",IFERROR(IF('Income Statement'!B4<=0,"n/a",'Balance Sheet'!B8/'Income Statement'!B4*365),"n/a")) | C28: =IF(COUNT('Balance Sheet'!C8,'Income Statement'!C4)<2,"n/a",IFERROR(IF('Income Statement'!C4<=0,"n/a",'Balance Sheet'!C8/'Income Statement'!C4*365),"n/a")) | D28: =IF(COUNT('Balance Sheet'!D8,'Income Statement'!D4)<2,"n/a",IFERROR(IF('Income Statement'!D4<=0,"n/a",'Balance Sheet'!D8/'Income Statement'!D4*365),"n/a")) | E28: =IF(COUNT('Balance Sheet'!E8,'Income Statement'!E4)<2,"n/a",IFERROR(IF('Income Statement'!E4<=0,"n/a",'Balance Sheet'!E8/'Income Statement'!E4*365),"n/a")) | F28: Trade receivables / revenue x 365
A29: Days Inventory Outstanding (DIO) | B29: =IF(COUNT('Balance Sheet'!B9,'Income Statement'!B5)<2,"n/a",IFERROR(IF('Income Statement'!B5<=0,"n/a",'Balance Sheet'!B9/'Income Statement'!B5*365),"n/a")) | C29: =IF(COUNT('Balance Sheet'!C9,'Income Statement'!C5)<2,"n/a",IFERROR(IF('Income Statement'!C5<=0,"n/a",'Balance Sheet'!C9/'Income Statement'!C5*365),"n/a")) | D29: =IF(COUNT('Balance Sheet'!D9,'Income Statement'!D5)<2,"n/a",IFERROR(IF('Income Statement'!D5<=0,"n/a",'Balance Sheet'!D9/'Income Statement'!D5*365),"n/a")) | E29: =IF(COUNT('Balance Sheet'!E9,'Income Statement'!E5)<2,"n/a",IFERROR(IF('Income Statement'!E5<=0,"n/a",'Balance Sheet'!E9/'Income Statement'!E5*365),"n/a")) | F29: Inventory / COGS x 365
A30: Days Payable Outstanding (DPO) | B30: =IF(COUNT('Balance Sheet'!B14,'Income Statement'!B5)<2,"n/a",IFERROR(IF('Income Statement'!B5<=0,"n/a",'Balance Sheet'!B14/'Income Statement'!B5*365),"n/a")) | C30: =IF(COUNT('Balance Sheet'!C14,'Income Statement'!C5)<2,"n/a",IFERROR(IF('Income Statement'!C5<=0,"n/a",'Balance Sheet'!C14/'Income Statement'!C5*365),"n/a")) | D30: =IF(COUNT('Balance Sheet'!D14,'Income Statement'!D5)<2,"n/a",IFERROR(IF('Income Statement'!D5<=0,"n/a",'Balance Sheet'!D14/'Income Statement'!D5*365),"n/a")) | E30: =IF(COUNT('Balance Sheet'!E14,'Income Statement'!E5)<2,"n/a",IFERROR(IF('Income Statement'!E5<=0,"n/a",'Balance Sheet'!E14/'Income Statement'!E5*365),"n/a")) | F30: Accounts payable / COGS x 365
A31: Cash Conversion Cycle (CCC) | B31: =IF(COUNT('Ratios'!B28,'Ratios'!B29,'Ratios'!B30)=3,'Ratios'!B28+'Ratios'!B29-'Ratios'!B30,IF(AND(COUNT('Ratios'!B28,'Ratios'!B30)=2,COUNT('Balance Sheet'!B9)=0),'Ratios'!B28-'Ratios'!B30,"n/a")) | C31: =IF(COUNT('Ratios'!C28,'Ratios'!C29,'Ratios'!C30)=3,'Ratios'!C28+'Ratios'!C29-'Ratios'!C30,IF(AND(COUNT('Ratios'!C28,'Ratios'!C30)=2,COUNT('Balance Sheet'!C9)=0),'Ratios'!C28-'Ratios'!C30,"n/a")) | D31: =IF(COUNT('Ratios'!D28,'Ratios'!D29,'Ratios'!D30)=3,'Ratios'!D28+'Ratios'!D29-'Ratios'!D30,IF(AND(COUNT('Ratios'!D28,'Ratios'!D30)=2,COUNT('Balance Sheet'!D9)=0),'Ratios'!D28-'Ratios'!D30,"n/a")) | E31: =IF(COUNT('Ratios'!E28,'Ratios'!E29,'Ratios'!E30)=3,'Ratios'!E28+'Ratios'!E29-'Ratios'!E30,IF(AND(COUNT('Ratios'!E28,'Ratios'!E30)=2,COUNT('Balance Sheet'!E9)=0),'Ratios'!E28-'Ratios'!E30,"n/a")) | F31: DSO + DIO - DPO (DIO = 0 if no inventory is reported)
A32: 5. Cash-flow quality
A33: Operating Cash Flow / Net Income | B33: =IF(COUNT('Cash Flow'!B4,'Income Statement'!B12)<2,"n/a",IFERROR(IF('Income Statement'!B12<=0,"n/a",'Cash Flow'!B4/'Income Statement'!B12),"n/a")) | C33: =IF(COUNT('Cash Flow'!C4,'Income Statement'!C12)<2,"n/a",IFERROR(IF('Income Statement'!C12<=0,"n/a",'Cash Flow'!C4/'Income Statement'!C12),"n/a")) | D33: =IF(COUNT('Cash Flow'!D4,'Income Statement'!D12)<2,"n/a",IFERROR(IF('Income Statement'!D12<=0,"n/a",'Cash Flow'!D4/'Income Statement'!D12),"n/a")) | E33: =IF(COUNT('Cash Flow'!E4,'Income Statement'!E12)<2,"n/a",IFERROR(IF('Income Statement'!E12<=0,"n/a",'Cash Flow'!E4/'Income Statement'!E12),"n/a")) | F33: CFO / net income (only if NI > 0)
A34: Free Cash Flow | B34: =IF(COUNT('Cash Flow'!B6)<1,"n/a",IFERROR('Cash Flow'!B6,"n/a")) | C34: =IF(COUNT('Cash Flow'!C6)<1,"n/a",IFERROR('Cash Flow'!C6,"n/a")) | D34: =IF(COUNT('Cash Flow'!D6)<1,"n/a",IFERROR('Cash Flow'!D6,"n/a")) | E34: =IF(COUNT('Cash Flow'!E6)<1,"n/a",IFERROR('Cash Flow'!E6,"n/a")) | F34: CFO - |capex|, millions
A35: FCF Margin | B35: =IF(COUNT('Cash Flow'!B6,'Income Statement'!B4)<2,"n/a",IFERROR('Cash Flow'!B6/'Income Statement'!B4,"n/a")) | C35: =IF(COUNT('Cash Flow'!C6,'Income Statement'!C4)<2,"n/a",IFERROR('Cash Flow'!C6/'Income Statement'!C4,"n/a")) | D35: =IF(COUNT('Cash Flow'!D6,'Income Statement'!D4)<2,"n/a",IFERROR('Cash Flow'!D6/'Income Statement'!D4,"n/a")) | E35: =IF(COUNT('Cash Flow'!E6,'Income Statement'!E4)<2,"n/a",IFERROR('Cash Flow'!E6/'Income Statement'!E4,"n/a")) | F35: FCF / revenue
A36: Capex / Revenue | B36: =IF(COUNT('Cash Flow'!B5,'Income Statement'!B4)<2,"n/a",IFERROR(ABS('Cash Flow'!B5)/'Income Statement'!B4,"n/a")) | C36: =IF(COUNT('Cash Flow'!C5,'Income Statement'!C4)<2,"n/a",IFERROR(ABS('Cash Flow'!C5)/'Income Statement'!C4,"n/a")) | D36: =IF(COUNT('Cash Flow'!D5,'Income Statement'!D4)<2,"n/a",IFERROR(ABS('Cash Flow'!D5)/'Income Statement'!D4,"n/a")) | E36: =IF(COUNT('Cash Flow'!E5,'Income Statement'!E4)<2,"n/a",IFERROR(ABS('Cash Flow'!E5)/'Income Statement'!E4,"n/a")) | F36: |Capex| / revenue
A37: Sloan Accrual Ratio | B37: =IF(COUNT('Income Statement'!B12,'Cash Flow'!B4,'Balance Sheet'!B13)<3,"n/a",IFERROR(('Income Statement'!B12-'Cash Flow'!B4)/'Balance Sheet'!B13,"n/a")) | C37: =IF(COUNT('Income Statement'!C12,'Cash Flow'!C4,'Balance Sheet'!C13)<3,"n/a",IFERROR(('Income Statement'!C12-'Cash Flow'!C4)/'Balance Sheet'!C13,"n/a")) | D37: =IF(COUNT('Income Statement'!D12,'Cash Flow'!D4,'Balance Sheet'!D13)<3,"n/a",IFERROR(('Income Statement'!D12-'Cash Flow'!D4)/'Balance Sheet'!D13,"n/a")) | E37: =IF(COUNT('Income Statement'!E12,'Cash Flow'!E4,'Balance Sheet'!E13)<3,"n/a",IFERROR(('Income Statement'!E12-'Cash Flow'!E4)/'Balance Sheet'!E13,"n/a")) | F37: (NI - CFO) / total assets
A38: 6. Growth (year over year)
A39: Revenue YoY Growth | B39: n/a | C39: =IF(COUNT('Income Statement'!C4,'Income Statement'!B4)<2,"n/a",IFERROR(IF('Income Statement'!B4=0,"n/a",('Income Statement'!C4-'Income Statement'!B4)/ABS('Income Statement'!B4)),"n/a")) | D39: =IF(COUNT('Income Statement'!D4,'Income Statement'!C4)<2,"n/a",IFERROR(IF('Income Statement'!C4=0,"n/a",('Income Statement'!D4-'Income Statement'!C4)/ABS('Income Statement'!C4)),"n/a")) | E39: =IF(COUNT('Income Statement'!E4,'Income Statement'!D4)<2,"n/a",IFERROR(IF('Income Statement'!D4=0,"n/a",('Income Statement'!E4-'Income Statement'!D4)/ABS('Income Statement'!D4)),"n/a"))
A40: Operating Income YoY Growth | B40: n/a | C40: =IF(COUNT('Income Statement'!C8,'Income Statement'!B8)<2,"n/a",IFERROR(IF('Income Statement'!B8=0,"n/a",('Income Statement'!C8-'Income Statement'!B8)/ABS('Income Statement'!B8)),"n/a")) | D40: =IF(COUNT('Income Statement'!D8,'Income Statement'!C8)<2,"n/a",IFERROR(IF('Income Statement'!C8=0,"n/a",('Income Statement'!D8-'Income Statement'!C8)/ABS('Income Statement'!C8)),"n/a")) | E40: =IF(COUNT('Income Statement'!E8,'Income Statement'!D8)<2,"n/a",IFERROR(IF('Income Statement'!D8=0,"n/a",('Income Statement'!E8-'Income Statement'!D8)/ABS('Income Statement'!D8)),"n/a"))
...

Sheet DuPont
A1: Apple Inc. (AAPL) - DuPont Analysis
A2: ROE split into its drivers. EBIT = operating income; ending balances. The check rows must be 0.
A3: Component | B3: FY2022 | C3: FY2023 | D3: FY2024 | E3: FY2025
A4: 3-step: ROE = Net margin x Asset turnover x Equity multiplier
A5: Net Profit Margin | B5: =IF(COUNT('Ratios'!B11)<1,"n/a",IFERROR('Ratios'!B11,"n/a")) | C5: =IF(COUNT('Ratios'!C11)<1,"n/a",IFERROR('Ratios'!C11,"n/a")) | D5: =IF(COUNT('Ratios'!D11)<1,"n/a",IFERROR('Ratios'!D11,"n/a")) | E5: =IF(COUNT('Ratios'!E11)<1,"n/a",IFERROR('Ratios'!E11,"n/a"))
A6: Asset Turnover | B6: =IF(COUNT('Ratios'!B24)<1,"n/a",IFERROR('Ratios'!B24,"n/a")) | C6: =IF(COUNT('Ratios'!C24)<1,"n/a",IFERROR('Ratios'!C24,"n/a")) | D6: =IF(COUNT('Ratios'!D24)<1,"n/a",IFERROR('Ratios'!D24,"n/a")) | E6: =IF(COUNT('Ratios'!E24)<1,"n/a",IFERROR('Ratios'!E24,"n/a"))
A7: Financial Leverage | B7: =IF(COUNT('Ratios'!B21)<1,"n/a",IFERROR('Ratios'!B21,"n/a")) | C7: =IF(COUNT('Ratios'!C21)<1,"n/a",IFERROR('Ratios'!C21,"n/a")) | D7: =IF(COUNT('Ratios'!D21)<1,"n/a",IFERROR('Ratios'!D21,"n/a")) | E7: =IF(COUNT('Ratios'!E21)<1,"n/a",IFERROR('Ratios'!E21,"n/a"))
A8: 3-Step DuPont ROE | B8: =IF(COUNT('DuPont'!B5,'DuPont'!B6,'DuPont'!B7)<3,"n/a",IFERROR('DuPont'!B5*'DuPont'!B6*'DuPont'!B7,"n/a")) | C8: =IF(COUNT('DuPont'!C5,'DuPont'!C6,'DuPont'!C7)<3,"n/a",IFERROR('DuPont'!C5*'DuPont'!C6*'DuPont'!C7,"n/a")) | D8: =IF(COUNT('DuPont'!D5,'DuPont'!D6,'DuPont'!D7)<3,"n/a",IFERROR('DuPont'!D5*'DuPont'!D6*'DuPont'!D7,"n/a")) | E8: =IF(COUNT('DuPont'!E5,'DuPont'!E6,'DuPont'!E7)<3,"n/a",IFERROR('DuPont'!E5*'DuPont'!E6*'DuPont'!E7,"n/a"))
A9: Actual Reported ROE | B9: =IF(COUNT('Ratios'!B15)<1,"n/a",IFERROR('Ratios'!B15,"n/a")) | C9: =IF(COUNT('Ratios'!C15)<1,"n/a",IFERROR('Ratios'!C15,"n/a")) | D9: =IF(COUNT('Ratios'!D15)<1,"n/a",IFERROR('Ratios'!D15,"n/a")) | E9: =IF(COUNT('Ratios'!E15)<1,"n/a",IFERROR('Ratios'!E15,"n/a"))
A10: Check: 3-step - ROE | B10: =IF(COUNT('DuPont'!B8,'DuPont'!B9)<2,"n/a",IFERROR('DuPont'!B8-'DuPont'!B9,"n/a")) | C10: =IF(COUNT('DuPont'!C8,'DuPont'!C9)<2,"n/a",IFERROR('DuPont'!C8-'DuPont'!C9,"n/a")) | D10: =IF(COUNT('DuPont'!D8,'DuPont'!D9)<2,"n/a",IFERROR('DuPont'!D8-'DuPont'!D9,"n/a")) | E10: =IF(COUNT('DuPont'!E8,'DuPont'!E9)<2,"n/a",IFERROR('DuPont'!E8-'DuPont'!E9,"n/a")) | F10: should be 0
A12: 5-step: ROE = Tax burden x Interest burden x EBIT margin x Asset turnover x Equity multiplier
A13: Tax Burden (NI / EBT) | B13: =IF(COUNT('Income Statement'!B12,'Income Statement'!B10)<2,"n/a",IFERROR('Income Statement'!B12/'Income Statement'!B10,"n/a")) | C13: =IF(COUNT('Income Statement'!C12,'Income Statement'!C10)<2,"n/a",IFERROR('Income Statement'!C12/'Income Statement'!C10,"n/a")) | D13: =IF(COUNT('Income Statement'!D12,'Income Statement'!D10)<2,"n/a",IFERROR('Income Statement'!D12/'Income Statement'!D10,"n/a")) | E13: =IF(COUNT('Income Statement'!E12,'Income Statement'!E10)<2,"n/a",IFERROR('Income Statement'!E12/'Income Statement'!E10,"n/a"))
A14: Interest Burden (EBT / EBIT) | B14: =IF(COUNT('Income Statement'!B10,'Income Statement'!B8)<2,"n/a",IFERROR('Income Statement'!B10/'Income Statement'!B8,"n/a")) | C14: =IF(COUNT('Income Statement'!C10,'Income Statement'!C8)<2,"n/a",IFERROR('Income Statement'!C10/'Income Statement'!C8,"n/a")) | D14: =IF(COUNT('Income Statement'!D10,'Income Statement'!D8)<2,"n/a",IFERROR('Income Statement'!D10/'Income Statement'!D8,"n/a")) | E14: =IF(COUNT('Income Statement'!E10,'Income Statement'!E8)<2,"n/a",IFERROR('Income Statement'!E10/'Income Statement'!E8,"n/a"))
A15: Operating Margin (EBIT / Rev) | B15: =IF(COUNT('Income Statement'!B8,'Income Statement'!B4)<2,"n/a",IFERROR('Income Statement'!B8/'Income Statement'!B4,"n/a")) | C15: =IF(COUNT('Income Statement'!C8,'Income Statement'!C4)<2,"n/a",IFERROR('Income Statement'!C8/'Income Statement'!C4,"n/a")) | D15: =IF(COUNT('Income Statement'!D8,'Income Statement'!D4)<2,"n/a",IFERROR('Income Statement'!D8/'Income Statement'!D4,"n/a")) | E15: =IF(COUNT('Income Statement'!E8,'Income Statement'!E4)<2,"n/a",IFERROR('Income Statement'!E8/'Income Statement'!E4,"n/a"))
A16: Asset Turnover (Rev / Assets) | B16: =IF(COUNT('Income Statement'!B4,'Balance Sheet'!B13)<2,"n/a",IFERROR('Income Statement'!B4/'Balance Sheet'!B13,"n/a")) | C16: =IF(COUNT('Income Statement'!C4,'Balance Sheet'!C13)<2,"n/a",IFERROR('Income Statement'!C4/'Balance Sheet'!C13,"n/a")) | D16: =IF(COUNT('Income Statement'!D4,'Balance Sheet'!D13)<2,"n/a",IFERROR('Income Statement'!D4/'Balance Sheet'!D13,"n/a")) | E16: =IF(COUNT('Income Statement'!E4,'Balance Sheet'!E13)<2,"n/a",IFERROR('Income Statement'!E4/'Balance Sheet'!E13,"n/a"))
A17: Financial Leverage (Assets / Eq) | B17: =IF(COUNT('Balance Sheet'!B13,'Balance Sheet'!B21)<2,"n/a",IFERROR('Balance Sheet'!B13/'Balance Sheet'!B21,"n/a")) | C17: =IF(COUNT('Balance Sheet'!C13,'Balance Sheet'!C21)<2,"n/a",IFERROR('Balance Sheet'!C13/'Balance Sheet'!C21,"n/a")) | D17: =IF(COUNT('Balance Sheet'!D13,'Balance Sheet'!D21)<2,"n/a",IFERROR('Balance Sheet'!D13/'Balance Sheet'!D21,"n/a")) | E17: =IF(COUNT('Balance Sheet'!E13,'Balance Sheet'!E21)<2,"n/a",IFERROR('Balance Sheet'!E13/'Balance Sheet'!E21,"n/a"))
A18: 5-Step DuPont ROE | B18: =IF(COUNT('DuPont'!B13,'DuPont'!B14,'DuPont'!B15,'DuPont'!B16,'DuPont'!B17)<5,"n/a",IFERROR('DuPont'!B13*'DuPont'!B14*'DuPont'!B15*'DuPont'!B16*'DuPont'!B17,"n/a")) | C18: =IF(COUNT('DuPont'!C13,'DuPont'!C14,'DuPont'!C15,'DuPont'!C16,'DuPont'!C17)<5,"n/a",IFERROR('DuPont'!C13*'DuPont'!C14*'DuPont'!C15*'DuPont'!C16*'DuPont'!C17,"n/a")) | D18: =IF(COUNT('DuPont'!D13,'DuPont'!D14,'DuPont'!D15,'DuPont'!D16,'DuPont'!D17)<5,"n/a",IFERROR('DuPont'!D13*'DuPont'!D14*'DuPont'!D15*'DuPont'!D16*'DuPont'!D17,"n/a")) | E18: =IF(COUNT('DuPont'!E13,'DuPont'!E14,'DuPont'!E15,'DuPont'!E16,'DuPont'!E17)<5,"n/a",IFERROR('DuPont'!E13*'DuPont'!E14*'DuPont'!E15*'DuPont'!E16*'DuPont'!E17,"n/a"))
A19: Check: 5-step - ROE | B19: =IF(COUNT('DuPont'!B18,'DuPont'!B9)<2,"n/a",IFERROR('DuPont'!B18-'DuPont'!B9,"n/a")) | C19: =IF(COUNT('DuPont'!C18,'DuPont'!C9)<2,"n/a",IFERROR('DuPont'!C18-'DuPont'!C9,"n/a")) | D19: =IF(COUNT('DuPont'!D18,'DuPont'!D9)<2,"n/a",IFERROR('DuPont'!D18-'DuPont'!D9,"n/a")) | E19: =IF(COUNT('DuPont'!E18,'DuPont'!E9)<2,"n/a",IFERROR('DuPont'!E18-'DuPont'!E9,"n/a")) | F19: should be 0

Sheet Altman Z
A1: Apple Inc. (AAPL) - Altman Z-Score
A2: Z = original 1968 model for public manufacturers (market value of equity). Z'' = 1995 model for non-manufacturers (book equity). Not for banks/insurers.
A3: Component | B3: FY2022 | C3: FY2023 | D3: FY2024 | E3: FY2025
A4: X1 (Working Capital / Assets) | B4: =IF(COUNT('Balance Sheet'!B22,'Balance Sheet'!B13)<2,"n/a",IFERROR('Balance Sheet'!B22/'Balance Sheet'!B13,"n/a")) | C4: =IF(COUNT('Balance Sheet'!C22,'Balance Sheet'!C13)<2,"n/a",IFERROR('Balance Sheet'!C22/'Balance Sheet'!C13,"n/a")) | D4: =IF(COUNT('Balance Sheet'!D22,'Balance Sheet'!D13)<2,"n/a",IFERROR('Balance Sheet'!D22/'Balance Sheet'!D13,"n/a")) | E4: =IF(COUNT('Balance Sheet'!E22,'Balance Sheet'!E13)<2,"n/a",IFERROR('Balance Sheet'!E22/'Balance Sheet'!E13,"n/a"))
A5: X2 (Retained Earnings / Assets) | B5: =IF(COUNT('Balance Sheet'!B20,'Balance Sheet'!B13)<2,"n/a",IFERROR('Balance Sheet'!B20/'Balance Sheet'!B13,"n/a")) | C5: =IF(COUNT('Balance Sheet'!C20,'Balance Sheet'!C13)<2,"n/a",IFERROR('Balance Sheet'!C20/'Balance Sheet'!C13,"n/a")) | D5: =IF(COUNT('Balance Sheet'!D20,'Balance Sheet'!D13)<2,"n/a",IFERROR('Balance Sheet'!D20/'Balance Sheet'!D13,"n/a")) | E5: =IF(COUNT('Balance Sheet'!E20,'Balance Sheet'!E13)<2,"n/a",IFERROR('Balance Sheet'!E20/'Balance Sheet'!E13,"n/a"))
A6: X3 (EBIT / Assets) | B6: =IF(COUNT('Income Statement'!B8,'Balance Sheet'!B13)<2,"n/a",IFERROR('Income Statement'!B8/'Balance Sheet'!B13,"n/a")) | C6: =IF(COUNT('Income Statement'!C8,'Balance Sheet'!C13)<2,"n/a",IFERROR('Income Statement'!C8/'Balance Sheet'!C13,"n/a")) | D6: =IF(COUNT('Income Statement'!D8,'Balance Sheet'!D13)<2,"n/a",IFERROR('Income Statement'!D8/'Balance Sheet'!D13,"n/a")) | E6: =IF(COUNT('Income Statement'!E8,'Balance Sheet'!E13)<2,"n/a",IFERROR('Income Statement'!E8/'Balance Sheet'!E13,"n/a")) | F6: EBIT = operating income
A7: X4 (Market Value of Equity / Liabilities) | B7: =IF(COUNT('Balance Sheet'!B27,'Balance Sheet'!B19)<2,"n/a",IFERROR('Balance Sheet'!B27/'Balance Sheet'!B19,"n/a")) | C7: =IF(COUNT('Balance Sheet'!C27,'Balance Sheet'!C19)<2,"n/a",IFERROR('Balance Sheet'!C27/'Balance Sheet'!C19,"n/a")) | D7: =IF(COUNT('Balance Sheet'!D27,'Balance Sheet'!D19)<2,"n/a",IFERROR('Balance Sheet'!D27/'Balance Sheet'!D19,"n/a")) | E7: =IF(COUNT('Balance Sheet'!E27,'Balance Sheet'!E19)<2,"n/a",IFERROR('Balance Sheet'!E27/'Balance Sheet'!E19,"n/a"))
A8: X4'' (Book Equity / Liabilities) | B8: =IF(COUNT('Balance Sheet'!B21,'Balance Sheet'!B19)<2,"n/a",IFERROR('Balance Sheet'!B21/'Balance Sheet'!B19,"n/a")) | C8: =IF(COUNT('Balance Sheet'!C21,'Balance Sheet'!C19)<2,"n/a",IFERROR('Balance Sheet'!C21/'Balance Sheet'!C19,"n/a")) | D8: =IF(COUNT('Balance Sheet'!D21,'Balance Sheet'!D19)<2,"n/a",IFERROR('Balance Sheet'!D21/'Balance Sheet'!D19,"n/a")) | E8: =IF(COUNT('Balance Sheet'!E21,'Balance Sheet'!E19)<2,"n/a",IFERROR('Balance Sheet'!E21/'Balance Sheet'!E19,"n/a"))
A9: X5 (Revenue / Assets) | B9: =IF(COUNT('Income Statement'!B4,'Balance Sheet'!B13)<2,"n/a",IFERROR('Income Statement'!B4/'Balance Sheet'!B13,"n/a")) | C9: =IF(COUNT('Income Statement'!C4,'Balance Sheet'!C13)<2,"n/a",IFERROR('Income Statement'!C4/'Balance Sheet'!C13,"n/a")) | D9: =IF(COUNT('Income Statement'!D4,'Balance Sheet'!D13)<2,"n/a",IFERROR('Income Statement'!D4/'Balance Sheet'!D13,"n/a")) | E9: =IF(COUNT('Income Statement'!E4,'Balance Sheet'!E13)<2,"n/a",IFERROR('Income Statement'!E4/'Balance Sheet'!E13,"n/a"))
A11: Altman Z-Score | B11: =IF(COUNT('Altman Z'!B4,'Altman Z'!B5,'Altman Z'!B6,'Altman Z'!B7,'Altman Z'!B9)<5,"n/a",IFERROR(1.2*'Altman Z'!B4+1.4*'Altman Z'!B5+3.3*'Altman Z'!B6+0.6*'Altman Z'!B7+0.999*'Altman Z'!B9,"n/a")) | C11: =IF(COUNT('Altman Z'!C4,'Altman Z'!C5,'Altman Z'!C6,'Altman Z'!C7,'Altman Z'!C9)<5,"n/a",IFERROR(1.2*'Altman Z'!C4+1.4*'Altman Z'!C5+3.3*'Altman Z'!C6+0.6*'Altman Z'!C7+0.999*'Altman Z'!C9,"n/a")) | D11: =IF(COUNT('Altman Z'!D4,'Altman Z'!D5,'Altman Z'!D6,'Altman Z'!D7,'Altman Z'!D9)<5,"n/a",IFERROR(1.2*'Altman Z'!D4+1.4*'Altman Z'!D5+3.3*'Altman Z'!D6+0.6*'Altman Z'!D7+0.999*'Altman Z'!D9,"n/a")) | E11: =IF(COUNT('Altman Z'!E4,'Altman Z'!E5,'Altman Z'!E6,'Altman Z'!E7,'Altman Z'!E9)<5,"n/a",IFERROR(1.2*'Altman Z'!E4+1.4*'Altman Z'!E5+3.3*'Altman Z'!E6+0.6*'Altman Z'!E7+0.999*'Altman Z'!E9,"n/a")) | F11: 1.2 X1 + 1.4 X2 + 3.3 X3 + 0.6 X4 + 0.999 X5
A12: Zone (Original) | B12: =IF(ISNUMBER('Altman Z'!B11),IF('Altman Z'!B11>2.99,"Safe Zone",IF('Altman Z'!B11>=1.81,"Grey Zone","Distress Zone")),"n/a") | C12: =IF(ISNUMBER('Altman Z'!C11),IF('Altman Z'!C11>2.99,"Safe Zone",IF('Altman Z'!C11>=1.81,"Grey Zone","Distress Zone")),"n/a") | D12: =IF(ISNUMBER('Altman Z'!D11),IF('Altman Z'!D11>2.99,"Safe Zone",IF('Altman Z'!D11>=1.81,"Grey Zone","Distress Zone")),"n/a") | E12: =IF(ISNUMBER('Altman Z'!E11),IF('Altman Z'!E11>2.99,"Safe Zone",IF('Altman Z'!E11>=1.81,"Grey Zone","Distress Zone")),"n/a") | F12: > 2.99 safe, 1.81-2.99 grey, < 1.81 distress
A13: Altman Z''-Score (Non-Mfg) | B13: =IF(COUNT('Altman Z'!B4,'Altman Z'!B5,'Altman Z'!B6,'Altman Z'!B8)<4,"n/a",IFERROR(6.56*'Altman Z'!B4+3.26*'Altman Z'!B5+6.72*'Altman Z'!B6+1.05*'Altman Z'!B8,"n/a")) | C13: =IF(COUNT('Altman Z'!C4,'Altman Z'!C5,'Altman Z'!C6,'Altman Z'!C8)<4,"n/a",IFERROR(6.56*'Altman Z'!C4+3.26*'Altman Z'!C5+6.72*'Altman Z'!C6+1.05*'Altman Z'!C8,"n/a")) | D13: =IF(COUNT('Altman Z'!D4,'Altman Z'!D5,'Altman Z'!D6,'Altman Z'!D8)<4,"n/a",IFERROR(6.56*'Altman Z'!D4+3.26*'Altman Z'!D5+6.72*'Altman Z'!D6+1.05*'Altman Z'!D8,"n/a")) | E13: =IF(COUNT('Altman Z'!E4,'Altman Z'!E5,'Altman Z'!E6,'Altman Z'!E8)<4,"n/a",IFERROR(6.56*'Altman Z'!E4+3.26*'Altman Z'!E5+6.72*'Altman Z'!E6+1.05*'Altman Z'!E8,"n/a")) | F13: 6.56 X1 + 3.26 X2 + 6.72 X3 + 1.05 X4''
A14: Zone (Non-Mfg) | B14: =IF(ISNUMBER('Altman Z'!B13),IF('Altman Z'!B13>2.6,"Safe Zone",IF('Altman Z'!B13>=1.1,"Grey Zone","Distress Zone")),"n/a") | C14: =IF(ISNUMBER('Altman Z'!C13),IF('Altman Z'!C13>2.6,"Safe Zone",IF('Altman Z'!C13>=1.1,"Grey Zone","Distress Zone")),"n/a") | D14: =IF(ISNUMBER('Altman Z'!D13),IF('Altman Z'!D13>2.6,"Safe Zone",IF('Altman Z'!D13>=1.1,"Grey Zone","Distress Zone")),"n/a") | E14: =IF(ISNUMBER('Altman Z'!E13),IF('Altman Z'!E13>2.6,"Safe Zone",IF('Altman Z'!E13>=1.1,"Grey Zone","Distress Zone")),"n/a") | F14: > 2.60 safe, 1.10-2.60 grey, < 1.10 distress

Sheet Piotroski
A1: Apple Inc. (AAPL) - Piotroski F-Score
A2: Piotroski (2000): 9 yes/no signals for year t vs t-1. ROA and turnover use beginning-of-year assets. Total shown only when all 9 signals are measurable.
A3: Helper / signal | B3: FY2022 | C3: FY2023 | D3: FY2024 | E3: FY2025
A4: Helper rows
A5: ROA (NI / beginning assets) | B5: n/a | C5: =IF(COUNT('Income Statement'!C12,'Balance Sheet'!B13)<2,"n/a",IFERROR('Income Statement'!C12/'Balance Sheet'!B13,"n/a")) | D5: =IF(COUNT('Income Statement'!D12,'Balance Sheet'!C13)<2,"n/a",IFERROR('Income Statement'!D12/'Balance Sheet'!C13,"n/a")) | E5: =IF(COUNT('Income Statement'!E12,'Balance Sheet'!D13)<2,"n/a",IFERROR('Income Statement'!E12/'Balance Sheet'!D13,"n/a"))
A6: Asset Turnover (Sales / beginning assets) | B6: n/a | C6: =IF(COUNT('Income Statement'!C4,'Balance Sheet'!B13)<2,"n/a",IFERROR('Income Statement'!C4/'Balance Sheet'!B13,"n/a")) | D6: =IF(COUNT('Income Statement'!D4,'Balance Sheet'!C13)<2,"n/a",IFERROR('Income Statement'!D4/'Balance Sheet'!C13,"n/a")) | E6: =IF(COUNT('Income Statement'!E4,'Balance Sheet'!D13)<2,"n/a",IFERROR('Income Statement'!E4/'Balance Sheet'!D13,"n/a"))
A7: Long-Term Debt / avg. Assets | B7: n/a | C7: =IF(COUNT('Balance Sheet'!C13,'Balance Sheet'!B13)<2,"n/a",IF(COUNT('Balance Sheet'!C17)=1,'Balance Sheet'!C17/AVERAGE('Balance Sheet'!C13,'Balance Sheet'!B13),IF(N('Balance Sheet'!C18)=0,0,"n/a"))) | D7: =IF(COUNT('Balance Sheet'!D13,'Balance Sheet'!C13)<2,"n/a",IF(COUNT('Balance Sheet'!D17)=1,'Balance Sheet'!D17/AVERAGE('Balance Sheet'!D13,'Balance Sheet'!C13),IF(N('Balance Sheet'!D18)=0,0,"n/a"))) | E7: =IF(COUNT('Balance Sheet'!E13,'Balance Sheet'!D13)<2,"n/a",IF(COUNT('Balance Sheet'!E17)=1,'Balance Sheet'!E17/AVERAGE('Balance Sheet'!E13,'Balance Sheet'!D13),IF(N('Balance Sheet'!E18)=0,0,"n/a"))) | F7: no debt reported at all -> 0
A8: Current Ratio | B8: =IF(COUNT('Balance Sheet'!B10,'Balance Sheet'!B16)<2,"n/a",IFERROR('Balance Sheet'!B10/'Balance Sheet'!B16,"n/a")) | C8: =IF(COUNT('Balance Sheet'!C10,'Balance Sheet'!C16)<2,"n/a",IFERROR('Balance Sheet'!C10/'Balance Sheet'!C16,"n/a")) | D8: =IF(COUNT('Balance Sheet'!D10,'Balance Sheet'!D16)<2,"n/a",IFERROR('Balance Sheet'!D10/'Balance Sheet'!D16,"n/a")) | E8: =IF(COUNT('Balance Sheet'!E10,'Balance Sheet'!E16)<2,"n/a",IFERROR('Balance Sheet'!E10/'Balance Sheet'!E16,"n/a"))
A9: Gross Margin | B9: =IF(COUNT('Income Statement'!B6,'Income Statement'!B4)<2,"n/a",IFERROR('Income Statement'!B6/'Income Statement'!B4,"n/a")) | C9: =IF(COUNT('Income Statement'!C6,'Income Statement'!C4)<2,"n/a",IFERROR('Income Statement'!C6/'Income Statement'!C4,"n/a")) | D9: =IF(COUNT('Income Statement'!D6,'Income Statement'!D4)<2,"n/a",IFERROR('Income Statement'!D6/'Income Statement'!D4,"n/a")) | E9: =IF(COUNT('Income Statement'!E6,'Income Statement'!E4)<2,"n/a",IFERROR('Income Statement'!E6/'Income Statement'!E4,"n/a"))
A10: Shares (outstanding, else diluted avg.) | B10: =IF(COUNT('Balance Sheet'!B23)=1,'Balance Sheet'!B23,IF(COUNT('Income Statement'!B14)=1,'Income Statement'!B14,"n/a")) | C10: =IF(COUNT('Balance Sheet'!C23)=1,'Balance Sheet'!C23,IF(COUNT('Income Statement'!C14)=1,'Income Statement'!C14,"n/a")) | D10: =IF(COUNT('Balance Sheet'!D23)=1,'Balance Sheet'!D23,IF(COUNT('Income Statement'!D14)=1,'Income Statement'!D14,"n/a")) | E10: =IF(COUNT('Balance Sheet'!E23)=1,'Balance Sheet'!E23,IF(COUNT('Income Statement'!E14)=1,'Income Statement'!E14,"n/a"))
A12: Signals (1 = pass, 0 = fail, n/a = not measurable)
A13: 1. Positive ROA (NI / beginning assets > 0) | B13: =IF(COUNT('Piotroski'!B5)<1,"n/a",IF('Piotroski'!B5>0,1,0)) | C13: =IF(COUNT('Piotroski'!C5)<1,"n/a",IF('Piotroski'!C5>0,1,0)) | D13: =IF(COUNT('Piotroski'!D5)<1,"n/a",IF('Piotroski'!D5>0,1,0)) | E13: =IF(COUNT('Piotroski'!E5)<1,"n/a",IF('Piotroski'!E5>0,1,0))
A14: 2. Positive Operating Cash Flow (CFO > 0) | B14: =IF(COUNT('Cash Flow'!B4)<1,"n/a",IF('Cash Flow'!B4>0,1,0)) | C14: =IF(COUNT('Cash Flow'!C4)<1,"n/a",IF('Cash Flow'!C4>0,1,0)) | D14: =IF(COUNT('Cash Flow'!D4)<1,"n/a",IF('Cash Flow'!D4>0,1,0)) | E14: =IF(COUNT('Cash Flow'!E4)<1,"n/a",IF('Cash Flow'!E4>0,1,0))
A15: 3. Higher ROA than last year | B15: n/a | C15: =IF(COUNT('Piotroski'!C5,'Piotroski'!B5)<2,"n/a",IF('Piotroski'!C5>'Piotroski'!B5,1,0)) | D15: =IF(COUNT('Piotroski'!D5,'Piotroski'!C5)<2,"n/a",IF('Piotroski'!D5>'Piotroski'!C5,1,0)) | E15: =IF(COUNT('Piotroski'!E5,'Piotroski'!D5)<2,"n/a",IF('Piotroski'!E5>'Piotroski'!D5,1,0))
A16: 4. Quality of Earnings (CFO > Net Income) | B16: =IF(COUNT('Cash Flow'!B4,'Income Statement'!B12)<2,"n/a",IF('Cash Flow'!B4>'Income Statement'!B12,1,0)) | C16: =IF(COUNT('Cash Flow'!C4,'Income Statement'!C12)<2,"n/a",IF('Cash Flow'!C4>'Income Statement'!C12,1,0)) | D16: =IF(COUNT('Cash Flow'!D4,'Income Statement'!D12)<2,"n/a",IF('Cash Flow'!D4>'Income Statement'!D12,1,0)) | E16: =IF(COUNT('Cash Flow'!E4,'Income Statement'!E12)<2,"n/a",IF('Cash Flow'!E4>'Income Statement'!E12,1,0))
A17: 5. Lower Long-Term Debt / avg. Assets | B17: n/a | C17: =IF(COUNT('Piotroski'!C7,'Piotroski'!B7)<2,"n/a",IF(OR('Piotroski'!C7<'Piotroski'!B7,AND('Piotroski'!C7=0,'Piotroski'!B7=0)),1,0)) | D17: =IF(COUNT('Piotroski'!D7,'Piotroski'!C7)<2,"n/a",IF(OR('Piotroski'!D7<'Piotroski'!C7,AND('Piotroski'!D7=0,'Piotroski'!C7=0)),1,0)) | E17: =IF(COUNT('Piotroski'!E7,'Piotroski'!D7)<2,"n/a",IF(OR('Piotroski'!E7<'Piotroski'!D7,AND('Piotroski'!E7=0,'Piotroski'!D7=0)),1,0))
A18: 6. Higher Current Ratio | B18: n/a | C18: =IF(COUNT('Piotroski'!C8,'Piotroski'!B8)<2,"n/a",IF('Piotroski'!C8>'Piotroski'!B8,1,0)) | D18: =IF(COUNT('Piotroski'!D8,'Piotroski'!C8)<2,"n/a",IF('Piotroski'!D8>'Piotroski'!C8,1,0)) | E18: =IF(COUNT('Piotroski'!E8,'Piotroski'!D8)<2,"n/a",IF('Piotroski'!E8>'Piotroski'!D8,1,0))
A19: 7. No New Shares Issued | B19: n/a | C19: =IF(COUNT('Piotroski'!C10,'Piotroski'!B10)<2,"n/a",IF('Piotroski'!C10<='Piotroski'!B10,1,0)) | D19: =IF(COUNT('Piotroski'!D10,'Piotroski'!C10)<2,"n/a",IF('Piotroski'!D10<='Piotroski'!C10,1,0)) | E19: =IF(COUNT('Piotroski'!E10,'Piotroski'!D10)<2,"n/a",IF('Piotroski'!E10<='Piotroski'!D10,1,0))
A20: 8. Higher Gross Margin | B20: n/a | C20: =IF(COUNT('Piotroski'!C9,'Piotroski'!B9)<2,"n/a",IF('Piotroski'!C9>'Piotroski'!B9,1,0)) | D20: =IF(COUNT('Piotroski'!D9,'Piotroski'!C9)<2,"n/a",IF('Piotroski'!D9>'Piotroski'!C9,1,0)) | E20: =IF(COUNT('Piotroski'!E9,'Piotroski'!D9)<2,"n/a",IF('Piotroski'!E9>'Piotroski'!D9,1,0))
A21: 9. Higher Asset Turnover (Sales / beginning assets) | B21: n/a | C21: =IF(COUNT('Piotroski'!C6,'Piotroski'!B6)<2,"n/a",IF('Piotroski'!C6>'Piotroski'!B6,1,0)) | D21: =IF(COUNT('Piotroski'!D6,'Piotroski'!C6)<2,"n/a",IF('Piotroski'!D6>'Piotroski'!C6,1,0)) | E21: =IF(COUNT('Piotroski'!E6,'Piotroski'!D6)<2,"n/a",IF('Piotroski'!E6>'Piotroski'!D6,1,0))
A22: Total Piotroski F-Score | B22: =IF(COUNT(B13:B21)=9,SUM(B13:B21),"n/a") | C22: =IF(COUNT(C13:C21)=9,SUM(C13:C21),"n/a") | D22: =IF(COUNT(D13:D21)=9,SUM(D13:D21),"n/a") | E22: =IF(COUNT(E13:E21)=9,SUM(E13:E21),"n/a")
A23: Signals Available | B23: =COUNT(B13:B21)&"/9" | C23: =COUNT(C13:C21)&"/9" | D23: =COUNT(D13:D21)&"/9" | E23: =COUNT(E13:E21)&"/9"
A24: Interpretation | B24: =IF(ISNUMBER('Piotroski'!B22),IF('Piotroski'!B22>=8,"Strong (8-9)",IF('Piotroski'!B22>=5,"Moderate (5-7)","Weak (0-4)")),"n/a") | C24: =IF(ISNUMBER('Piotroski'!C22),IF('Piotroski'!C22>=8,"Strong (8-9)",IF('Piotroski'!C22>=5,"Moderate (5-7)","Weak (0-4)")),"n/a") | D24: =IF(ISNUMBER('Piotroski'!D22),IF('Piotroski'!D22>=8,"Strong (8-9)",IF('Piotroski'!D22>=5,"Moderate (5-7)","Weak (0-4)")),"n/a") | E24: =IF(ISNUMBER('Piotroski'!E22),IF('Piotroski'!E22>=8,"Strong (8-9)",IF('Piotroski'!E22>=5,"Moderate (5-7)","Weak (0-4)")),"n/a")

Sheet Common-Size
A1: Apple Inc. (AAPL) - Common-Size Statements
A2: Income statement lines as % of revenue; balance-sheet lines as % of total assets.
A3: Line item | B3: FY2022 | C3: FY2023 | D3: FY2024 | E3: FY2025
A4: Income statement (% of revenue)
A5: Total Revenue | B5: =IF(COUNT('Income Statement'!B4,'Income Statement'!B4)<2,"n/a",IFERROR(IF('Income Statement'!B4<=0,"n/a",'Income Statement'!B4/'Income Statement'!B4),"n/a")) | C5: =IF(COUNT('Income Statement'!C4,'Income Statement'!C4)<2,"n/a",IFERROR(IF('Income Statement'!C4<=0,"n/a",'Income Statement'!C4/'Income Statement'!C4),"n/a")) | D5: =IF(COUNT('Income Statement'!D4,'Income Statement'!D4)<2,"n/a",IFERROR(IF('Income Statement'!D4<=0,"n/a",'Income Statement'!D4/'Income Statement'!D4),"n/a")) | E5: =IF(COUNT('Income Statement'!E4,'Income Statement'!E4)<2,"n/a",IFERROR(IF('Income Statement'!E4<=0,"n/a",'Income Statement'!E4/'Income Statement'!E4),"n/a"))
A6: Cost of Revenue (COGS) | B6: =IF(COUNT('Income Statement'!B5,'Income Statement'!B4)<2,"n/a",IFERROR(IF('Income Statement'!B4<=0,"n/a",'Income Statement'!B5/'Income Statement'!B4),"n/a")) | C6: =IF(COUNT('Income Statement'!C5,'Income Statement'!C4)<2,"n/a",IFERROR(IF('Income Statement'!C4<=0,"n/a",'Income Statement'!C5/'Income Statement'!C4),"n/a")) | D6: =IF(COUNT('Income Statement'!D5,'Income Statement'!D4)<2,"n/a",IFERROR(IF('Income Statement'!D4<=0,"n/a",'Income Statement'!D5/'Income Statement'!D4),"n/a")) | E6: =IF(COUNT('Income Statement'!E5,'Income Statement'!E4)<2,"n/a",IFERROR(IF('Income Statement'!E4<=0,"n/a",'Income Statement'!E5/'Income Statement'!E4),"n/a"))
A7: Gross Profit | B7: =IF(COUNT('Income Statement'!B6,'Income Statement'!B4)<2,"n/a",IFERROR(IF('Income Statement'!B4<=0,"n/a",'Income Statement'!B6/'Income Statement'!B4),"n/a")) | C7: =IF(COUNT('Income Statement'!C6,'Income Statement'!C4)<2,"n/a",IFERROR(IF('Income Statement'!C4<=0,"n/a",'Income Statement'!C6/'Income Statement'!C4),"n/a")) | D7: =IF(COUNT('Income Statement'!D6,'Income Statement'!D4)<2,"n/a",IFERROR(IF('Income Statement'!D4<=0,"n/a",'Income Statement'!D6/'Income Statement'!D4),"n/a")) | E7: =IF(COUNT('Income Statement'!E6,'Income Statement'!E4)<2,"n/a",IFERROR(IF('Income Statement'!E4<=0,"n/a",'Income Statement'!E6/'Income Statement'!E4),"n/a"))
A8: Operating Expenses | B8: =IF(COUNT('Income Statement'!B7,'Income Statement'!B4)<2,"n/a",IFERROR(IF('Income Statement'!B4<=0,"n/a",'Income Statement'!B7/'Income Statement'!B4),"n/a")) | C8: =IF(COUNT('Income Statement'!C7,'Income Statement'!C4)<2,"n/a",IFERROR(IF('Income Statement'!C4<=0,"n/a",'Income Statement'!C7/'Income Statement'!C4),"n/a")) | D8: =IF(COUNT('Income Statement'!D7,'Income Statement'!D4)<2,"n/a",IFERROR(IF('Income Statement'!D4<=0,"n/a",'Income Statement'!D7/'Income Statement'!D4),"n/a")) | E8: =IF(COUNT('Income Statement'!E7,'Income Statement'!E4)<2,"n/a",IFERROR(IF('Income Statement'!E4<=0,"n/a",'Income Statement'!E7/'Income Statement'!E4),"n/a"))
A9: Operating Income (EBIT) | B9: =IF(COUNT('Income Statement'!B8,'Income Statement'!B4)<2,"n/a",IFERROR(IF('Income Statement'!B4<=0,"n/a",'Income Statement'!B8/'Income Statement'!B4),"n/a")) | C9: =IF(COUNT('Income Statement'!C8,'Income Statement'!C4)<2,"n/a",IFERROR(IF('Income Statement'!C4<=0,"n/a",'Income Statement'!C8/'Income Statement'!C4),"n/a")) | D9: =IF(COUNT('Income Statement'!D8,'Income Statement'!D4)<2,"n/a",IFERROR(IF('Income Statement'!D4<=0,"n/a",'Income Statement'!D8/'Income Statement'!D4),"n/a")) | E9: =IF(COUNT('Income Statement'!E8,'Income Statement'!E4)<2,"n/a",IFERROR(IF('Income Statement'!E4<=0,"n/a",'Income Statement'!E8/'Income Statement'!E4),"n/a"))
A10: Interest Expense | B10: =IF(COUNT('Income Statement'!B9,'Income Statement'!B4)<2,"n/a",IFERROR(IF('Income Statement'!B4<=0,"n/a",'Income Statement'!B9/'Income Statement'!B4),"n/a")) | C10: =IF(COUNT('Income Statement'!C9,'Income Statement'!C4)<2,"n/a",IFERROR(IF('Income Statement'!C4<=0,"n/a",'Income Statement'!C9/'Income Statement'!C4),"n/a")) | D10: =IF(COUNT('Income Statement'!D9,'Income Statement'!D4)<2,"n/a",IFERROR(IF('Income Statement'!D4<=0,"n/a",'Income Statement'!D9/'Income Statement'!D4),"n/a")) | E10: =IF(COUNT('Income Statement'!E9,'Income Statement'!E4)<2,"n/a",IFERROR(IF('Income Statement'!E4<=0,"n/a",'Income Statement'!E9/'Income Statement'!E4),"n/a"))
A11: Pre-tax Income (EBT) | B11: =IF(COUNT('Income Statement'!B10,'Income Statement'!B4)<2,"n/a",IFERROR(IF('Income Statement'!B4<=0,"n/a",'Income Statement'!B10/'Income Statement'!B4),"n/a")) | C11: =IF(COUNT('Income Statement'!C10,'Income Statement'!C4)<2,"n/a",IFERROR(IF('Income Statement'!C4<=0,"n/a",'Income Statement'!C10/'Income Statement'!C4),"n/a")) | D11: =IF(COUNT('Income Statement'!D10,'Income Statement'!D4)<2,"n/a",IFERROR(IF('Income Statement'!D4<=0,"n/a",'Income Statement'!D10/'Income Statement'!D4),"n/a")) | E11: =IF(COUNT('Income Statement'!E10,'Income Statement'!E4)<2,"n/a",IFERROR(IF('Income Statement'!E4<=0,"n/a",'Income Statement'!E10/'Income Statement'!E4),"n/a"))
A12: Income Tax Expense | B12: =IF(COUNT('Income Statement'!B11,'Income Statement'!B4)<2,"n/a",IFERROR(IF('Income Statement'!B4<=0,"n/a",'Income Statement'!B11/'Income Statement'!B4),"n/a")) | C12: =IF(COUNT('Income Statement'!C11,'Income Statement'!C4)<2,"n/a",IFERROR(IF('Income Statement'!C4<=0,"n/a",'Income Statement'!C11/'Income Statement'!C4),"n/a")) | D12: =IF(COUNT('Income Statement'!D11,'Income Statement'!D4)<2,"n/a",IFERROR(IF('Income Statement'!D4<=0,"n/a",'Income Statement'!D11/'Income Statement'!D4),"n/a")) | E12: =IF(COUNT('Income Statement'!E11,'Income Statement'!E4)<2,"n/a",IFERROR(IF('Income Statement'!E4<=0,"n/a",'Income Statement'!E11/'Income Statement'!E4),"n/a"))
A13: Net Income | B13: =IF(COUNT('Income Statement'!B12,'Income Statement'!B4)<2,"n/a",IFERROR(IF('Income Statement'!B4<=0,"n/a",'Income Statement'!B12/'Income Statement'!B4),"n/a")) | C13: =IF(COUNT('Income Statement'!C12,'Income Statement'!C4)<2,"n/a",IFERROR(IF('Income Statement'!C4<=0,"n/a",'Income Statement'!C12/'Income Statement'!C4),"n/a")) | D13: =IF(COUNT('Income Statement'!D12,'Income Statement'!D4)<2,"n/a",IFERROR(IF('Income Statement'!D4<=0,"n/a",'Income Statement'!D12/'Income Statement'!D4),"n/a")) | E13: =IF(COUNT('Income Statement'!E12,'Income Statement'!E4)<2,"n/a",IFERROR(IF('Income Statement'!E4<=0,"n/a",'Income Statement'!E12/'Income Statement'!E4),"n/a"))
A15: Balance sheet (% of total assets)
A16: BS: Cash and Cash Equivalents | B16: =IF(COUNT('Balance Sheet'!B4,'Balance Sheet'!B13)<2,"n/a",IFERROR(IF('Balance Sheet'!B13<=0,"n/a",'Balance Sheet'!B4/'Balance Sheet'!B13),"n/a")) | C16: =IF(COUNT('Balance Sheet'!C4,'Balance Sheet'!C13)<2,"n/a",IFERROR(IF('Balance Sheet'!C13<=0,"n/a",'Balance Sheet'!C4/'Balance Sheet'!C13),"n/a")) | D16: =IF(COUNT('Balance Sheet'!D4,'Balance Sheet'!D13)<2,"n/a",IFERROR(IF('Balance Sheet'!D13<=0,"n/a",'Balance Sheet'!D4/'Balance Sheet'!D13),"n/a")) | E16: =IF(COUNT('Balance Sheet'!E4,'Balance Sheet'!E13)<2,"n/a",IFERROR(IF('Balance Sheet'!E13<=0,"n/a",'Balance Sheet'!E4/'Balance Sheet'!E13),"n/a"))
A17: BS: Short-Term Investments | B17: =IF(COUNT('Balance Sheet'!B5,'Balance Sheet'!B13)<2,"n/a",IFERROR(IF('Balance Sheet'!B13<=0,"n/a",'Balance Sheet'!B5/'Balance Sheet'!B13),"n/a")) | C17: =IF(COUNT('Balance Sheet'!C5,'Balance Sheet'!C13)<2,"n/a",IFERROR(IF('Balance Sheet'!C13<=0,"n/a",'Balance Sheet'!C5/'Balance Sheet'!C13),"n/a")) | D17: =IF(COUNT('Balance Sheet'!D5,'Balance Sheet'!D13)<2,"n/a",IFERROR(IF('Balance Sheet'!D13<=0,"n/a",'Balance Sheet'!D5/'Balance Sheet'!D13),"n/a")) | E17: =IF(COUNT('Balance Sheet'!E5,'Balance Sheet'!E13)<2,"n/a",IFERROR(IF('Balance Sheet'!E13<=0,"n/a",'Balance Sheet'!E5/'Balance Sheet'!E13),"n/a"))
A18: BS: Cash + Short-Term Investments | B18: =IF(COUNT('Balance Sheet'!B6,'Balance Sheet'!B13)<2,"n/a",IFERROR(IF('Balance Sheet'!B13<=0,"n/a",'Balance Sheet'!B6/'Balance Sheet'!B13),"n/a")) | C18: =IF(COUNT('Balance Sheet'!C6,'Balance Sheet'!C13)<2,"n/a",IFERROR(IF('Balance Sheet'!C13<=0,"n/a",'Balance Sheet'!C6/'Balance Sheet'!C13),"n/a")) | D18: =IF(COUNT('Balance Sheet'!D6,'Balance Sheet'!D13)<2,"n/a",IFERROR(IF('Balance Sheet'!D13<=0,"n/a",'Balance Sheet'!D6/'Balance Sheet'!D13),"n/a")) | E18: =IF(COUNT('Balance Sheet'!E6,'Balance Sheet'!E13)<2,"n/a",IFERROR(IF('Balance Sheet'!E13<=0,"n/a",'Balance Sheet'!E6/'Balance Sheet'!E13),"n/a"))
A19: BS: Total Receivables | B19: =IF(COUNT('Balance Sheet'!B7,'Balance Sheet'!B13)<2,"n/a",IFERROR(IF('Balance Sheet'!B13<=0,"n/a",'Balance Sheet'!B7/'Balance Sheet'!B13),"n/a")) | C19: =IF(COUNT('Balance Sheet'!C7,'Balance Sheet'!C13)<2,"n/a",IFERROR(IF('Balance Sheet'!C13<=0,"n/a",'Balance Sheet'!C7/'Balance Sheet'!C13),"n/a")) | D19: =IF(COUNT('Balance Sheet'!D7,'Balance Sheet'!D13)<2,"n/a",IFERROR(IF('Balance Sheet'!D13<=0,"n/a",'Balance Sheet'!D7/'Balance Sheet'!D13),"n/a")) | E19: =IF(COUNT('Balance Sheet'!E7,'Balance Sheet'!E13)<2,"n/a",IFERROR(IF('Balance Sheet'!E13<=0,"n/a",'Balance Sheet'!E7/'Balance Sheet'!E13),"n/a"))
A20: BS: Accounts Receivable (trade) | B20: =IF(COUNT('Balance Sheet'!B8,'Balance Sheet'!B13)<2,"n/a",IFERROR(IF('Balance Sheet'!B13<=0,"n/a",'Balance Sheet'!B8/'Balance Sheet'!B13),"n/a")) | C20: =IF(COUNT('Balance Sheet'!C8,'Balance Sheet'!C13)<2,"n/a",IFERROR(IF('Balance Sheet'!C13<=0,"n/a",'Balance Sheet'!C8/'Balance Sheet'!C13),"n/a")) | D20: =IF(COUNT('Balance Sheet'!D8,'Balance Sheet'!D13)<2,"n/a",IFERROR(IF('Balance Sheet'!D13<=0,"n/a",'Balance Sheet'!D8/'Balance Sheet'!D13),"n/a")) | E20: =IF(COUNT('Balance Sheet'!E8,'Balance Sheet'!E13)<2,"n/a",IFERROR(IF('Balance Sheet'!E13<=0,"n/a",'Balance Sheet'!E8/'Balance Sheet'!E13),"n/a"))
A21: BS: Inventory | B21: =IF(COUNT('Balance Sheet'!B9,'Balance Sheet'!B13)<2,"n/a",IFERROR(IF('Balance Sheet'!B13<=0,"n/a",'Balance Sheet'!B9/'Balance Sheet'!B13),"n/a")) | C21: =IF(COUNT('Balance Sheet'!C9,'Balance Sheet'!C13)<2,"n/a",IFERROR(IF('Balance Sheet'!C13<=0,"n/a",'Balance Sheet'!C9/'Balance Sheet'!C13),"n/a")) | D21: =IF(COUNT('Balance Sheet'!D9,'Balance Sheet'!D13)<2,"n/a",IFERROR(IF('Balance Sheet'!D13<=0,"n/a",'Balance Sheet'!D9/'Balance Sheet'!D13),"n/a")) | E21: =IF(COUNT('Balance Sheet'!E9,'Balance Sheet'!E13)<2,"n/a",IFERROR(IF('Balance Sheet'!E13<=0,"n/a",'Balance Sheet'!E9/'Balance Sheet'!E13),"n/a"))
A22: BS: Total Current Assets | B22: =IF(COUNT('Balance Sheet'!B10,'Balance Sheet'!B13)<2,"n/a",IFERROR(IF('Balance Sheet'!B13<=0,"n/a",'Balance Sheet'!B10/'Balance Sheet'!B13),"n/a")) | C22: =IF(COUNT('Balance Sheet'!C10,'Balance Sheet'!C13)<2,"n/a",IFERROR(IF('Balance Sheet'!C13<=0,"n/a",'Balance Sheet'!C10/'Balance Sheet'!C13),"n/a")) | D22: =IF(COUNT('Balance Sheet'!D10,'Balance Sheet'!D13)<2,"n/a",IFERROR(IF('Balance Sheet'!D13<=0,"n/a",'Balance Sheet'!D10/'Balance Sheet'!D13),"n/a")) | E22: =IF(COUNT('Balance Sheet'!E10,'Balance Sheet'!E13)<2,"n/a",IFERROR(IF('Balance Sheet'!E13<=0,"n/a",'Balance Sheet'!E10/'Balance Sheet'!E13),"n/a"))
A23: BS: Net PP&E | B23: =IF(COUNT('Balance Sheet'!B11,'Balance Sheet'!B13)<2,"n/a",IFERROR(IF('Balance Sheet'!B13<=0,"n/a",'Balance Sheet'!B11/'Balance Sheet'!B13),"n/a")) | C23: =IF(COUNT('Balance Sheet'!C11,'Balance Sheet'!C13)<2,"n/a",IFERROR(IF('Balance Sheet'!C13<=0,"n/a",'Balance Sheet'!C11/'Balance Sheet'!C13),"n/a")) | D23: =IF(COUNT('Balance Sheet'!D11,'Balance Sheet'!D13)<2,"n/a",IFERROR(IF('Balance Sheet'!D13<=0,"n/a",'Balance Sheet'!D11/'Balance Sheet'!D13),"n/a")) | E23: =IF(COUNT('Balance Sheet'!E11,'Balance Sheet'!E13)<2,"n/a",IFERROR(IF('Balance Sheet'!E13<=0,"n/a",'Balance Sheet'!E11/'Balance Sheet'!E13),"n/a"))
