Workbook

Sheet Summary
A1: Apple Inc. (AAPL) - DCF Valuation
A2: USD millions, except per-share values. Blue cells on 'Assumptions' are inputs; everything else is a formula.
A4: VALUATION SUMMARY
B5: Gordon Growth | C5: Exit Multiple
A6: WACC | B6: =WACC!B22 -> 0.10598195 | C6: =WACC!B22 -> 0.10598195
A7: Enterprise value (millions) | B7: =DCF!B37 -> 1369197.7 | C7: =DCF!C37 -> 1585163.7
A8: Equity value (millions) | B8: =DCF!B41 -> 1347252.7 | C8: =DCF!C41 -> 1563218.7
A9: Implied value per share | B9: =DCF!B43 -> 92.31438 | C9: =DCF!C43 -> 107.11247
A10: Current share price | B10: =Assumptions!B7 -> 333.02 | C10: =Assumptions!B7 -> 333.02
A11: Upside / (downside) | B11: =DCF!B45 -> -0.72279629 | C11: =DCF!C45 -> -0.67836024
A12: Terminal value as % of EV | B12: =DCF!B47 -> 0.66738406 | C12: =DCF!C47 -> 0.71270035
A14: AUDIT: PYTHON APP RESULT AT EXPORT TIME (STATIC)
A15: App implied value per share (static number) | B15: 92.31438 | C15: 107.11247
A16: Difference: Excel formula - app | B16: =IFERROR(B9-B15,"n/a") -> 0 | C16: =IFERROR(C9-C15,"n/a") -> 0
A17: Should be ~0.00 until you change an input. After that, the Excel formulas are the live answer.
A19: HOW TO USE THIS WORKBOOK
A20: 1. Go to 'Assumptions'. Blue text on yellow = inputs you may change.
A21: 2. Every other number is a formula; follow it with Formulas > Trace Precedents (Excel).
A22: 3. 'DCF' shows the 5-year FCFF forecast, discounting, terminal value and the equity bridge.
A23: 4. 'Sensitivity' recalculates the share price for different WACC / g / exit multiple values.
A24: 5. Educational model only - not investment advice.

Sheet Assumptions
A1: Apple Inc. (AAPL) - DCF Valuation
A2: USD millions, except per-share values. Blue cells on 'Assumptions' are inputs; everything else is a formula.
A4: COMPANY & MARKET DATA
A5: Ticker | B5: AAPL | H5: Source: Yahoo Finance via yfinance
A6: Company name | B6: Apple Inc.
A7: Current share price | B7: 333.02 | H7: USD per share
A8: Shares outstanding (millions) | B8: 14594.18 | H8: Basic shares from Yahoo Finance
A9: Market capitalization - E (millions) | B9: 4860154 | H9: Market value of equity, used for WACC weights
A10: Total debt - D (millions) | B10: 84343.996 | H10: Includes lease liabilities as reported by Yahoo
A11: Cash & short-term investments (millions) | B11: 62399.001
A12: Base-year revenue FY2025 (millions) | B12: 416161 | H12: Last reported fiscal year = Year 0
A14: COST OF CAPITAL INPUTS
A15: Risk-free rate (Rf) | B15: 0.0529 | H15: 10-year US Treasury yield
A16: Equity beta | B16: 1.08 | H16: Sensitivity of the stock to the market
A17: Equity risk premium (ERP) | B17: 0.05 | H17: Extra return investors want for owning stocks
A18: Pre-tax cost of debt (Kd) | B18: 0.0629
A19: Tax rate for the debt tax shield | B19: 0.1561
A20: Use target weights? (1 = yes, 0 = market values) | B20: 0
A21: Target weight of equity (if used) | B21: 0.98294185
A23: TERMINAL VALUE & CONVENTIONS
A24: Perpetual growth rate (g) | B24: 0.025 | H24: Must be below WACC; usually 2%-3%
A25: Exit EV/EBITDA multiple | B25: 12 | H25: Applied to Year-5 EBITDA
A26: Mid-year convention (1 = yes, 0 = end of year) | B26: 1 | H26: Mid-year: year t cash flow discounted t - 0.5 years
A28: SENSITIVITY TABLE STEP SIZES
A29: WACC step | B29: 0.01
A30: Perpetual growth step | B30: 0.005
A31: Exit multiple step | B31: 2
A33: FORECAST ASSUMPTIONS (YEAR 1 TO YEAR 5)
A34: Driver | B34: Year 1 (FY2026E) | C34: Year 2 (FY2027E) | D34: Year 3 (FY2028E) | E34: Year 4 (FY2029E) | F34: Year 5 (FY2030E)
A35: Revenue growth | B35: 0.0181 | C35: 0.01629 | D35: 0.014661 | E35: 0.0131949 | F35: 0.01187541
A36: EBIT margin (% of revenue) | B36: 0.3197 | C36: 0.3197 | D36: 0.3197 | E36: 0.3197 | F36: 0.3197
A37: Tax rate on EBIT | B37: 0.1561 | C37: 0.1561 | D37: 0.1561 | E37: 0.1561 | F37: 0.1561
A38: D&A (% of revenue) | B38: 0.0281 | C38: 0.0281 | D38: 0.0281 | E38: 0.0281 | F38: 0.0281
A39: Capex (% of revenue) | B39: 0.0306 | C39: 0.0306 | D39: 0.0306 | E39: 0.0306 | F39: 0.0306
A40: Net working capital (% of revenue) | B40: 0.05 | C40: 0.05 | D40: 0.05 | E40: 0.05 | F40: 0.05
A42: Tip: change any blue cell and every sheet recalculates. Do not type over black (formula) cells.

Sheet Historicals
A1: Apple Inc. (AAPL) - DCF Valuation
A2: USD millions, except per-share values. Blue cells on 'Assumptions' are inputs; everything else is a formula.
A4: REPORTED HISTORICAL DATA (MILLIONS)
A5: Line item | B5: FY2022A | C5: FY2023A | D5: FY2024A | E5: FY2025A
A6: Revenue | B6: 394328 | C6: 383285 | D6: 391035 | E6: 416161
A7: EBIT (operating income) | B7: 119437 | C7: 114301 | D7: 123216 | E7: 133050
A8: Depreciation & amortization (D&A) | B8: 11104 | C8: 11519 | D8: 11445 | E8: 11698
A9: Capital expenditure (capex, positive = cash spent) | B9: 10708 | C9: 10959 | D9: 9447 | E9: 12715
A10: Increase in net working capital (positive = cash used) | B10: -1200 | C10: 6577 | D10: -3651 | E10: 25000
A11: Effective tax rate | B11: 0.16204462 | C11: 0.14719174 | D11: 0.24091185 | E11: 0.15610002
A13: NOPAT = EBIT x (1 - tax) | B13: =B7*(1-B11) -> 100082.88 | C13: =C7*(1-C11) -> 97476.837 | D13: =D7*(1-D11) -> 93531.805 | E13: =E7*(1-E11) -> 112280.89
A14: Free cash flow to firm (FCFF) | B14: =B13+B8-B9-B10 -> 101678.88 | C14: =C13+C8-C9-C10 -> 91459.837 | D14: =D13+D8-D9-D10 -> 99180.805 | E14: =E13+E8-E9-E10 -> 86263.892
A16: Revenue growth | C16: =C6/B6-1 -> -0.028004605 | D16: =D6/C6-1 -> 0.020219941 | E16: =E6/D6-1 -> 0.064255118
A17: EBIT margin | B17: =B7/B6 -> 0.30288744 | C17: =C7/C6 -> 0.29821412 | D17: =D7/D6 -> 0.31510223 | E17: =E7/E6 -> 0.319708
A18: D&A % of revenue | B18: =B8/B6 -> 0.028159299 | C18: =C8/C6 -> 0.030053355 | D18: =D8/D6 -> 0.02926848 | E18: =E8/E6 -> 0.028109313
A19: Capex % of revenue | B19: =B9/B6 -> 0.027155059 | C19: =C9/C6 -> 0.028592301 | D19: =D9/D6 -> 0.024158963 | E19: =E9/E6 -> 0.030553079
A21: Sign convention: Yahoo reports capex and 'Change In Working Capital' as cash flows (negative = cash out). Here capex is shown positive and the working-capital line is flipped so that an INCREASE in NWC is positive. FCFF = NOPAT + D&A - Capex - Increase in NWC.

Sheet WACC
A1: Apple Inc. (AAPL) - DCF Valuation
A2: USD millions, except per-share values. Blue cells on 'Assumptions' are inputs; everything else is a formula.
A4: COST OF EQUITY (CAPM)
A5: Risk-free rate (Rf) | B5: =Assumptions!B15 -> 0.0529
A6: Equity beta | B6: =Assumptions!B16 -> 1.08
A7: Equity risk premium (ERP) | B7: =Assumptions!B17 -> 0.05
A8: Cost of equity Ke = Rf + beta x ERP | B8: =B5+B6*B7 -> 0.1069
A10: COST OF DEBT
A11: Pre-tax cost of debt (Kd) | B11: =Assumptions!B18 -> 0.0629
A12: Tax rate | B12: =Assumptions!B19 -> 0.1561
A13: After-tax cost of debt Kd x (1 - t) | B13: =B11*(1-B12) -> 0.05308131
A15: CAPITAL STRUCTURE (MILLIONS)
A16: Equity - market capitalization (E) | B16: =Assumptions!B9 -> 4860154
A17: Debt (D) | B17: =Assumptions!B10 -> 84343.996
A18: Total capital V = E + D | B18: =B16+B17 -> 4944498
A19: Weight of equity E / V | B19: =IF(Assumptions!B20=1,Assumptions!B21,B16/B18) -> 0.98294185
A20: Weight of debt D / V | B20: =1-B19 -> 0.017058152
A22: WACC = We x Ke + Wd x Kd x (1 - t) | B22: =B19*B8+B20*B13 -> 0.10598195

Sheet DCF
A1: Apple Inc. (AAPL) - DCF Valuation
A2: USD millions, except per-share values. Blue cells on 'Assumptions' are inputs; everything else is a formula.
A4: FREE CASH FLOW FORECAST (MILLIONS)
B5: FY2025A (Year 0) | C5: Year 1 (FY2026E) | D5: Year 2 (FY2027E) | E5: Year 3 (FY2028E) | F5: Year 4 (FY2029E) | G5: Year 5 (FY2030E)
A6: Revenue growth | C6: =Assumptions!B35 -> 0.0181 | D6: =Assumptions!C35 -> 0.01629 | E6: =Assumptions!D35 -> 0.014661 | F6: =Assumptions!E35 -> 0.0131949 | G6: =Assumptions!F35 -> 0.01187541
A7: Revenue | B7: =Assumptions!B12 -> 416161 | C7: =B7*(1+C6) -> 423693.51 | D7: =C7*(1+D6) -> 430595.48 | E7: =D7*(1+E6) -> 436908.44 | F7: =E7*(1+F6) -> 442673.4 | G7: =F7*(1+G6) -> 447930.33
A8: EBIT margin | C8: =Assumptions!B36 -> 0.3197 | D8: =Assumptions!C36 -> 0.3197 | E8: =Assumptions!D36 -> 0.3197 | F8: =Assumptions!E36 -> 0.3197 | G8: =Assumptions!F36 -> 0.3197
A9: EBIT | C9: =C7*C8 -> 135454.82 | D9: =D7*D8 -> 137661.38 | E9: =E7*E8 -> 139679.63 | F9: =F7*F8 -> 141522.69 | G9: =G7*G8 -> 143203.33
A10: Tax rate | C10: =Assumptions!B37 -> 0.1561 | D10: =Assumptions!C37 -> 0.1561 | E10: =Assumptions!D37 -> 0.1561 | F10: =Assumptions!E37 -> 0.1561 | G10: =Assumptions!F37 -> 0.1561
A11: NOPAT = EBIT x (1 - tax) | C11: =C9*(1-C10) -> 114310.32 | D11: =D9*(1-D10) -> 116172.43 | E11: =E9*(1-E10) -> 117875.64 | F11: =F9*(1-F10) -> 119431 | G11: =G9*(1-G10) -> 120849.29
A12: D&A % of revenue | C12: =Assumptions!B38 -> 0.0281 | D12: =Assumptions!C38 -> 0.0281 | E12: =Assumptions!D38 -> 0.0281 | F12: =Assumptions!E38 -> 0.0281 | G12: =Assumptions!F38 -> 0.0281
A13: (+) D&A | C13: =C7*C12 -> 11905.788 | D13: =D7*D12 -> 12099.733 | E13: =E7*E12 -> 12277.127 | F13: =F7*F12 -> 12439.123 | G13: =G7*G12 -> 12586.842
A14: Capex % of revenue | C14: =Assumptions!B39 -> 0.0306 | D14: =Assumptions!C39 -> 0.0306 | E14: =Assumptions!D39 -> 0.0306 | F14: =Assumptions!E39 -> 0.0306 | G14: =Assumptions!F39 -> 0.0306
A15: (-) Capex | C15: =C7*C14 -> 12965.022 | D15: =D7*D14 -> 13176.222 | E15: =E7*E14 -> 13369.398 | F15: =F7*F14 -> 13545.806 | G15: =G7*G14 -> 13706.668
A16: NWC % of revenue | C16: =Assumptions!B40 -> 0.05 | D16: =Assumptions!C40 -> 0.05 | E16: =Assumptions!D40 -> 0.05 | F16: =Assumptions!E40 -> 0.05 | G16: =Assumptions!F40 -> 0.05
A17: Net working capital (NWC) | B17: =B7*Assumptions!B40 -> 20808.05 | C17: =C7*C16 -> 21184.676 | D17: =D7*D16 -> 21529.774 | E17: =E7*E16 -> 21845.422 | F17: =F7*F16 -> 22133.67 | G17: =G7*G16 -> 22396.517 | H17: Year-0 NWC = base revenue x Year-1 NWC %
A18: (-) Increase in NWC | C18: =C17-B17 -> 376.6257 | D18: =D17-C17 -> 345.09837 | E18: =E17-D17 -> 315.64802 | F18: =F17-E17 -> 288.24816 | G18: =G17-F17 -> 262.84641
A19: Free cash flow to firm (FCFF) | C19: =C11+C13-C15-C18 -> 112874.46 | D19: =D11+D13-D15-D18 -> 114750.85 | E19: =E11+E13-E15-E18 -> 116467.72 | F19: =F11+F13-F15-F18 -> 118036.06 | G19: =G11+G13-G15-G18 -> 119466.62
A21: Year number (t) | C21: 1 | D21: 2 | E21: 3 | F21: 4 | G21: 5
A22: Discount period | C22: =IF(Assumptions!$B$26=1,C21-0.5,C21) -> 0.5 | D22: =IF(Assumptions!$B$26=1,D21-0.5,D21) -> 1.5 | E22: =IF(Assumptions!$B$26=1,E21-0.5,E21) -> 2.5 | F22: =IF(Assumptions!$B$26=1,F21-0.5,F21) -> 3.5 | G22: =IF(Assumptions!$B$26=1,G21-0.5,G21) -> 4.5
A23: Discount factor = 1/(1+WACC)^period | C23: =1/(1+WACC!$B$22)^C22 -> 0.95088058 | D23: =1/(1+WACC!$B$22)^D22 -> 0.85976139 | E23: =1/(1+WACC!$B$22)^E22 -> 0.7773738 | F23: =1/(1+WACC!$B$22)^F22 -> 0.70288109 | G23: =1/(1+WACC!$B$22)^G22 -> 0.63552673
A24: Present value of FCFF | C24: =C19*C23 -> 107330.13 | D24: =D19*D23 -> 98658.349 | E24: =E19*E23 -> 90538.954 | F24: =F19*F23 -> 82965.318 | G24: =G19*G23 -> 75924.227
A26: Sum of PV of FCFF (Years 1-5) | B26: =SUM(C24:G24) -> 455416.98
A28: TERMINAL VALUE & EQUITY BRIDGE (MILLIONS)
B29: Gordon Growth | C29: Exit Multiple
A30: WACC | B30: =WACC!$B$22 -> 0.10598195 | C30: =WACC!$B$22 -> 0.10598195
A31: Terminal assumption (g | EV/EBITDA multiple) | B31: =Assumptions!B24 -> 0.025 | C31: =Assumptions!B25 -> 12
A32: Year-5 FCFF | B32: =$G$19 -> 119466.62 | C32: =$G$19 -> 119466.62
A33: Year-5 EBITDA = EBIT + D&A | B33: =$G$9+$G$13 -> 155790.17 | C33: =$G$9+$G$13 -> 155790.17
A34: Terminal value at end of Year 5 | B34: =IF(B30>B31,B32*(1+B31)/(B30-B31),NA()) -> 1512105.8 | C34: =C33*C31 -> 1869482
A35: PV of terminal value = TV / (1+WACC)^5 | B35: =B34/(1+B30)^$G$21 -> 913780.7 | C35: =C34/(1+C30)^$G$21 -> 1129746.7
A36: (+) Sum of PV of FCFF (Years 1-5) | B36: =$B$26 -> 455416.98 | C36: =$B$26 -> 455416.98
A37: Enterprise value (EV) | B37: =B35+B36 -> 1369197.7 | C37: =C35+C36 -> 1585163.7
A38: (-) Total debt | B38: =Assumptions!$B$10 -> 84343.996 | C38: =Assumptions!$B$10 -> 84343.996
A39: (+) Cash & short-term investments | B39: =Assumptions!$B$11 -> 62399.001 | C39: =Assumptions!$B$11 -> 62399.001
A40: Net debt = debt - cash | B40: =B38-B39 -> 21944.996 | C40: =C38-C39 -> 21944.996
A41: Equity value = EV - net debt | B41: =B37-B40 -> 1347252.7 | C41: =C37-C40 -> 1563218.7
A42: Shares outstanding (millions) | B42: =Assumptions!$B$8 -> 14594.18 | C42: =Assumptions!$B$8 -> 14594.18
A43: Implied value per share | B43: =B41/B42 -> 92.31438 | C43: =C41/C42 -> 107.11247
A44: Current share price | B44: =Assumptions!$B$7 -> 333.02 | C44: =Assumptions!$B$7 -> 333.02
...

Sheet Sensitivity
A1: Apple Inc. (AAPL) - DCF Valuation
A2: USD millions, except per-share values. Blue cells on 'Assumptions' are inputs; everything else is a formula.
A4: IMPLIED VALUE PER SHARE: WACC vs PERPETUAL GROWTH (GORDON GROWTH)
A5: WACC (rows) \ g (columns) | B5: =Assumptions!$B$24+(-2)*Assumptions!$B$30 -> 0.015 | C5: =Assumptions!$B$24+(-1)*Assumptions!$B$30 -> 0.02 | D5: =Assumptions!$B$24+(0)*Assumptions!$B$30 -> 0.025 | E5: =Assumptions!$B$24+(1)*Assumptions!$B$30 -> 0.03 | F5: =Assumptions!$B$24+(2)*Assumptions!$B$30 -> 0.035
A6: =WACC!$B$22+(-2)*Assumptions!$B$29 -> 0.085981953 | B6: =IF($A6>B$5,(SUMPRODUCT(DCF!$C$19:$G$19,(1+$A6)^(-DCF!$C$22:$G$22))+DCF!$G$19*(1+B$5)/($A6-B$5)/(1+$A6)^DCF!$G$21-DCF!$B$40)/DCF!$B$42,"n/a") -> 108.56119 | C6: =IF($A6>C$5,(SUMPRODUCT(DCF!$C$19:$G$19,(1+$A6)^(-DCF!$C$22:$G$22))+DCF!$G$19*(1+C$5)/($A6-C$5)/(1+$A6)^DCF!$G$21-DCF!$B$40)/DCF!$B$42,"n/a") -> 114.84428 | D6: =IF($A6>D$5,(SUMPRODUCT(DCF!$C$19:$G$19,(1+$A6)^(-DCF!$C$22:$G$22))+DCF!$G$19*(1+D$5)/($A6-D$5)/(1+$A6)^DCF!$G$21-DCF!$B$40)/DCF!$B$42,"n/a") -> 122.15769 | E6: =IF($A6>E$5,(SUMPRODUCT(DCF!$C$19:$G$19,(1+$A6)^(-DCF!$C$22:$G$22))+DCF!$G$19*(1+E$5)/($A6-E$5)/(1+$A6)^DCF!$G$21-DCF!$B$40)/DCF!$B$42,"n/a") -> 130.77749 | F6: =IF($A6>F$5,(SUMPRODUCT(DCF!$C$19:$G$19,(1+$A6)^(-DCF!$C$22:$G$22))+DCF!$G$19*(1+F$5)/($A6-F$5)/(1+$A6)^DCF!$G$21-DCF!$B$40)/DCF!$B$42,"n/a") -> 141.08804
A7: =WACC!$B$22+(-1)*Assumptions!$B$29 -> 0.095981953 | B7: =IF($A7>B$5,(SUMPRODUCT(DCF!$C$19:$G$19,(1+$A7)^(-DCF!$C$22:$G$22))+DCF!$G$19*(1+B$5)/($A7-B$5)/(1+$A7)^DCF!$G$21-DCF!$B$40)/DCF!$B$42,"n/a") -> 95.253566 | C7: =IF($A7>C$5,(SUMPRODUCT(DCF!$C$19:$G$19,(1+$A7)^(-DCF!$C$22:$G$22))+DCF!$G$19*(1+C$5)/($A7-C$5)/(1+$A7)^DCF!$G$21-DCF!$B$40)/DCF!$B$42,"n/a") -> 99.863817 | D7: =IF($A7>D$5,(SUMPRODUCT(DCF!$C$19:$G$19,(1+$A7)^(-DCF!$C$22:$G$22))+DCF!$G$19*(1+D$5)/($A7-D$5)/(1+$A7)^DCF!$G$21-DCF!$B$40)/DCF!$B$42,"n/a") -> 105.12356 | E7: =IF($A7>E$5,(SUMPRODUCT(DCF!$C$19:$G$19,(1+$A7)^(-DCF!$C$22:$G$22))+DCF!$G$19*(1+E$5)/($A7-E$5)/(1+$A7)^DCF!$G$21-DCF!$B$40)/DCF!$B$42,"n/a") -> 111.18046 | F7: =IF($A7>F$5,(SUMPRODUCT(DCF!$C$19:$G$19,(1+$A7)^(-DCF!$C$22:$G$22))+DCF!$G$19*(1+F$5)/($A7-F$5)/(1+$A7)^DCF!$G$21-DCF!$B$40)/DCF!$B$42,"n/a") -> 118.23058
A8: =WACC!$B$22+(0)*Assumptions!$B$29 -> 0.10598195 | B8: =IF($A8>B$5,(SUMPRODUCT(DCF!$C$19:$G$19,(1+$A8)^(-DCF!$C$22:$G$22))+DCF!$G$19*(1+B$5)/($A8-B$5)/(1+$A8)^DCF!$G$21-DCF!$B$40)/DCF!$B$42,"n/a") -> 84.888786 | C8: =IF($A8>C$5,(SUMPRODUCT(DCF!$C$19:$G$19,(1+$A8)^(-DCF!$C$22:$G$22))+DCF!$G$19*(1+C$5)/($A8-C$5)/(1+$A8)^DCF!$G$21-DCF!$B$40)/DCF!$B$42,"n/a") -> 88.385678 | D8: =IF($A8>D$5,(SUMPRODUCT(DCF!$C$19:$G$19,(1+$A8)^(-DCF!$C$22:$G$22))+DCF!$G$19*(1+D$5)/($A8-D$5)/(1+$A8)^DCF!$G$21-DCF!$B$40)/DCF!$B$42,"n/a") -> 92.31438 | E8: =IF($A8>E$5,(SUMPRODUCT(DCF!$C$19:$G$19,(1+$A8)^(-DCF!$C$22:$G$22))+DCF!$G$19*(1+E$5)/($A8-E$5)/(1+$A8)^DCF!$G$21-DCF!$B$40)/DCF!$B$42,"n/a") -> 96.76014 | F8: =IF($A8>F$5,(SUMPRODUCT(DCF!$C$19:$G$19,(1+$A8)^(-DCF!$C$22:$G$22))+DCF!$G$19*(1+F$5)/($A8-F$5)/(1+$A8)^DCF!$G$21-DCF!$B$40)/DCF!$B$42,"n/a") -> 101.83222
A9: =WACC!$B$22+(1)*Assumptions!$B$29 -> 0.11598195 | B9: =IF($A9>B$5,(SUMPRODUCT(DCF!$C$19:$G$19,(1+$A9)^(-DCF!$C$22:$G$22))+DCF!$G$19*(1+B$5)/($A9-B$5)/(1+$A9)^DCF!$G$21-DCF!$B$40)/DCF!$B$42,"n/a") -> 76.591044 | C9: =IF($A9>C$5,(SUMPRODUCT(DCF!$C$19:$G$19,(1+$A9)^(-DCF!$C$22:$G$22))+DCF!$G$19*(1+C$5)/($A9-C$5)/(1+$A9)^DCF!$G$21-DCF!$B$40)/DCF!$B$42,"n/a") -> 79.313588 | D9: =IF($A9>D$5,(SUMPRODUCT(DCF!$C$19:$G$19,(1+$A9)^(-DCF!$C$22:$G$22))+DCF!$G$19*(1+D$5)/($A9-D$5)/(1+$A9)^DCF!$G$21-DCF!$B$40)/DCF!$B$42,"n/a") -> 82.335371 | E9: =IF($A9>E$5,(SUMPRODUCT(DCF!$C$19:$G$19,(1+$A9)^(-DCF!$C$22:$G$22))+DCF!$G$19*(1+E$5)/($A9-E$5)/(1+$A9)^DCF!$G$21-DCF!$B$40)/DCF!$B$42,"n/a") -> 85.708599 | F9: =IF($A9>F$5,(SUMPRODUCT(DCF!$C$19:$G$19,(1+$A9)^(-DCF!$C$22:$G$22))+DCF!$G$19*(1+F$5)/($A9-F$5)/(1+$A9)^DCF!$G$21-DCF!$B$40)/DCF!$B$42,"n/a") -> 89.498367
A10: =WACC!$B$22+(2)*Assumptions!$B$29 -> 0.12598195 | B10: =IF($A10>B$5,(SUMPRODUCT(DCF!$C$19:$G$19,(1+$A10)^(-DCF!$C$22:$G$22))+DCF!$G$19*(1+B$5)/($A10-B$5)/(1+$A10)^DCF!$G$21-DCF!$B$40)/DCF!$B$42,"n/a") -> 69.800316 | C10: =IF($A10>C$5,(SUMPRODUCT(DCF!$C$19:$G$19,(1+$A10)^(-DCF!$C$22:$G$22))+DCF!$G$19*(1+C$5)/($A10-C$5)/(1+$A10)^DCF!$G$21-DCF!$B$40)/DCF!$B$42,"n/a") -> 71.965161 | D10: =IF($A10>D$5,(SUMPRODUCT(DCF!$C$19:$G$19,(1+$A10)^(-DCF!$C$22:$G$22))+DCF!$G$19*(1+D$5)/($A10-D$5)/(1+$A10)^DCF!$G$21-DCF!$B$40)/DCF!$B$42,"n/a") -> 74.344386 | E10: =IF($A10>E$5,(SUMPRODUCT(DCF!$C$19:$G$19,(1+$A10)^(-DCF!$C$22:$G$22))+DCF!$G$19*(1+E$5)/($A10-E$5)/(1+$A10)^DCF!$G$21-DCF!$B$40)/DCF!$B$42,"n/a") -> 76.971493 | F10: =IF($A10>F$5,(SUMPRODUCT(DCF!$C$19:$G$19,(1+$A10)^(-DCF!$C$22:$G$22))+DCF!$G$19*(1+F$5)/($A10-F$5)/(1+$A10)^DCF!$G$21-DCF!$B$40)/DCF!$B$42,"n/a") -> 79.887351
A13: IMPLIED VALUE PER SHARE: WACC vs EXIT EV/EBITDA MULTIPLE
A14: WACC (rows) \ Exit multiple (columns) | B14: =Assumptions!$B$25+(-2)*Assumptions!$B$31 -> 8 | C14: =Assumptions!$B$25+(-1)*Assumptions!$B$31 -> 10 | D14: =Assumptions!$B$25+(0)*Assumptions!$B$31 -> 12 | E14: =Assumptions!$B$25+(1)*Assumptions!$B$31 -> 14 | F14: =Assumptions!$B$25+(2)*Assumptions!$B$31 -> 16
A15: =WACC!$B$22+(-2)*Assumptions!$B$29 -> 0.085981953 | B15: =(SUMPRODUCT(DCF!$C$19:$G$19,(1+$A15)^(-DCF!$C$22:$G$22))+DCF!$C$33*B$14/(1+$A15)^DCF!$G$21-DCF!$B$40)/DCF!$B$42 -> 87.604092 | C15: =(SUMPRODUCT(DCF!$C$19:$G$19,(1+$A15)^(-DCF!$C$22:$G$22))+DCF!$C$33*C$14/(1+$A15)^DCF!$G$21-DCF!$B$40)/DCF!$B$42 -> 101.73849 | D15: =(SUMPRODUCT(DCF!$C$19:$G$19,(1+$A15)^(-DCF!$C$22:$G$22))+DCF!$C$33*D$14/(1+$A15)^DCF!$G$21-DCF!$B$40)/DCF!$B$42 -> 115.87289 | E15: =(SUMPRODUCT(DCF!$C$19:$G$19,(1+$A15)^(-DCF!$C$22:$G$22))+DCF!$C$33*E$14/(1+$A15)^DCF!$G$21-DCF!$B$40)/DCF!$B$42 -> 130.00728 | F15: =(SUMPRODUCT(DCF!$C$19:$G$19,(1+$A15)^(-DCF!$C$22:$G$22))+DCF!$C$33*F$14/(1+$A15)^DCF!$G$21-DCF!$B$40)/DCF!$B$42 -> 144.14168
A16: =WACC!$B$22+(-1)*Assumptions!$B$29 -> 0.095981953 | B16: =(SUMPRODUCT(DCF!$C$19:$G$19,(1+$A16)^(-DCF!$C$22:$G$22))+DCF!$C$33*B$14/(1+$A16)^DCF!$G$21-DCF!$B$40)/DCF!$B$42 -> 84.375975 | C16: =(SUMPRODUCT(DCF!$C$19:$G$19,(1+$A16)^(-DCF!$C$22:$G$22))+DCF!$C$33*C$14/(1+$A16)^DCF!$G$21-DCF!$B$40)/DCF!$B$42 -> 97.877205 | D16: =(SUMPRODUCT(DCF!$C$19:$G$19,(1+$A16)^(-DCF!$C$22:$G$22))+DCF!$C$33*D$14/(1+$A16)^DCF!$G$21-DCF!$B$40)/DCF!$B$42 -> 111.37844 | E16: =(SUMPRODUCT(DCF!$C$19:$G$19,(1+$A16)^(-DCF!$C$22:$G$22))+DCF!$C$33*E$14/(1+$A16)^DCF!$G$21-DCF!$B$40)/DCF!$B$42 -> 124.87967 | F16: =(SUMPRODUCT(DCF!$C$19:$G$19,(1+$A16)^(-DCF!$C$22:$G$22))+DCF!$C$33*F$14/(1+$A16)^DCF!$G$21-DCF!$B$40)/DCF!$B$42 -> 138.3809
A17: =WACC!$B$22+(0)*Assumptions!$B$29 -> 0.10598195 | B17: =(SUMPRODUCT(DCF!$C$19:$G$19,(1+$A17)^(-DCF!$C$22:$G$22))+DCF!$C$33*B$14/(1+$A17)^DCF!$G$21-DCF!$B$40)/DCF!$B$42 -> 81.308883 | C17: =(SUMPRODUCT(DCF!$C$19:$G$19,(1+$A17)^(-DCF!$C$22:$G$22))+DCF!$C$33*C$14/(1+$A17)^DCF!$G$21-DCF!$B$40)/DCF!$B$42 -> 94.210678 | D17: =(SUMPRODUCT(DCF!$C$19:$G$19,(1+$A17)^(-DCF!$C$22:$G$22))+DCF!$C$33*D$14/(1+$A17)^DCF!$G$21-DCF!$B$40)/DCF!$B$42 -> 107.11247 | E17: =(SUMPRODUCT(DCF!$C$19:$G$19,(1+$A17)^(-DCF!$C$22:$G$22))+DCF!$C$33*E$14/(1+$A17)^DCF!$G$21-DCF!$B$40)/DCF!$B$42 -> 120.01427 | F17: =(SUMPRODUCT(DCF!$C$19:$G$19,(1+$A17)^(-DCF!$C$22:$G$22))+DCF!$C$33*F$14/(1+$A17)^DCF!$G$21-DCF!$B$40)/DCF!$B$42 -> 132.91606
A18: =WACC!$B$22+(1)*Assumptions!$B$29 -> 0.11598195 | B18: =(SUMPRODUCT(DCF!$C$19:$G$19,(1+$A18)^(-DCF!$C$22:$G$22))+DCF!$C$33*B$14/(1+$A18)^DCF!$G$21-DCF!$B$40)/DCF!$B$42 -> 78.393224 | C18: =(SUMPRODUCT(DCF!$C$19:$G$19,(1+$A18)^(-DCF!$C$22:$G$22))+DCF!$C$33*C$14/(1+$A18)^DCF!$G$21-DCF!$B$40)/DCF!$B$42 -> 90.72724 | D18: =(SUMPRODUCT(DCF!$C$19:$G$19,(1+$A18)^(-DCF!$C$22:$G$22))+DCF!$C$33*D$14/(1+$A18)^DCF!$G$21-DCF!$B$40)/DCF!$B$42 -> 103.06126 | E18: =(SUMPRODUCT(DCF!$C$19:$G$19,(1+$A18)^(-DCF!$C$22:$G$22))+DCF!$C$33*E$14/(1+$A18)^DCF!$G$21-DCF!$B$40)/DCF!$B$42 -> 115.39527 | F18: =(SUMPRODUCT(DCF!$C$19:$G$19,(1+$A18)^(-DCF!$C$22:$G$22))+DCF!$C$33*F$14/(1+$A18)^DCF!$G$21-DCF!$B$40)/DCF!$B$42 -> 127.72929
A19: =WACC!$B$22+(2)*Assumptions!$B$29 -> 0.12598195 | B19: =(SUMPRODUCT(DCF!$C$19:$G$19,(1+$A19)^(-DCF!$C$22:$G$22))+DCF!$C$33*B$14/(1+$A19)^DCF!$G$21-DCF!$B$40)/DCF!$B$42 -> 75.620063 | C19: =(SUMPRODUCT(DCF!$C$19:$G$19,(1+$A19)^(-DCF!$C$22:$G$22))+DCF!$C$33*C$14/(1+$A19)^DCF!$G$21-DCF!$B$40)/DCF!$B$42 -> 87.416021 | D19: =(SUMPRODUCT(DCF!$C$19:$G$19,(1+$A19)^(-DCF!$C$22:$G$22))+DCF!$C$33*D$14/(1+$A19)^DCF!$G$21-DCF!$B$40)/DCF!$B$42 -> 99.211979 | E19: =(SUMPRODUCT(DCF!$C$19:$G$19,(1+$A19)^(-DCF!$C$22:$G$22))+DCF!$C$33*E$14/(1+$A19)^DCF!$G$21-DCF!$B$40)/DCF!$B$42 -> 111.00794 | F19: =(SUMPRODUCT(DCF!$C$19:$G$19,(1+$A19)^(-DCF!$C$22:$G$22))+DCF!$C$33*F$14/(1+$A19)^DCF!$G$21-DCF!$B$40)/DCF!$B$42 -> 122.80389
A22: Green = above the current share price, red = below. Centre cell = base case. Each cell recomputes the full DCF.
